Workbook

Sheet Machine_Clean
A1: Row_Key | B1: QR_Code_Clean | C1: QR_Code_Raw | D1: QR_Prefix | E1: Dup_QR_Count | F1: No_Clean | G1: Location_Clean | H1: Location_Raw | I1: Factory_Group | J1: Department_Clean | K1: Department_Raw | L1: Dept_Prefix | M1: Section_Clean | N1: Section_Source | O1: Responsible_Group | P1: Cost_Center_Clean | Q1: Category_Clean | R1: Machine_Desc_Clean | S1: Machine_Desc_Raw | T1: Production_Name_Clean | U1: Related_QR_Ref | V1: Status_Clean | W1: Search_Text | X1: Quality_Flag | Y1: Info_Note
A2: =IF($B2="","NO_QR#"&TEXT(ROW()-1,"0000"),$B2&"#"&TEXT(ROW()-1,"0000")) -> AS-955#0001 | B2: =IF('query (2)'!B2="","",TRIM(UPPER('query (2)'!B2))) -> AS-955 | C2: =IF('query (2)'!B2="","",'query (2)'!B2) -> AS-955 | D2: =IF($B2="","",IFERROR(_xlfn.TEXTBEFORE($B2,"-"),"NO_PREFIX")) -> AS | E2: =IF($B2="","",COUNTIF($B$2:$B$974,$B2)) -> 1 | F2: =IF('query (2)'!A2="","",IFERROR(VALUE('query (2)'!A2),"")) -> 1 | G2: =IF('query (2)'!C2="","UNKNOWN",IFERROR(INDEX(Cleaning_Rules!$B$15:$B$20,MATCH(TRIM(UPPER('query (2)'!C2)),Cleaning_Rules!$A$15:$A$20,0)),"UNKNOWN")) -> FACTORY3 | H2: =IF('query (2)'!C2="","",'query (2)'!C2) -> FACTORY3 | I2: {=_xlfn.IFS($G2="UNKNOWN","UNKNOWN",OR($G2="FACTORY1",$G2="FACTORY2",$G2="FACTORY3"),"PLANT",TRUE,"SHARED")} -> PLANT | J2: =IF('query (2)'!D2="","UNKNOWN",IF(COUNTIF(Cleaning_Rules!$A$6:$A$11,TRIM('query (2)'!D2))>0,"UNKNOWN",IFERROR(INDEX(Cleaning_Rules!$B$24:$B$28,MATCH(TRIM(UPPER('query (2)'!D2)),Cleaning_Rules!$A$24:$A$28,0)),TRIM(UPPER('query (2)'!D2))))) -> KWD5 | K2: =IF('query (2)'!D2="","",'query (2)'!D2) -> KWD5 | L2: =IF($J2="UNKNOWN","",_xlfn.TEXTBEFORE($J2,{"0","1","2","3","4","5","6","7","8","9"," ","-","."},1,,,$J2)) -> KWD | M2: =IF('query (2)'!I2<>"",TRIM(UPPER('query (2)'!I2)),IF($L2="","UNKNOWN",$L2)) -> KWD | N2: =IF('query (2)'!I2<>"","SOURCE",IF($L2="","UNKNOWN","DERIVED")) -> SOURCE | O2: =IF('query (2)'!E2="","NOT_SPECIFIED",TRIM(UPPER('query (2)'!E2))) -> ASSEMBLY | P2: =IF('query (2)'!F2="","",TRIM(UPPER('query (2)'!F2))) -> 1016-KW5AI | Q2: =IF('query (2)'!G2="","UNKNOWN",IFERROR(INDEX(Cleaning_Rules!$B$38:$B$46,MATCH(TRIM(UPPER('query (2)'!G2)),Cleaning_Rules!$A$38:$A$46,0)),"UNKNOWN")) -> ASSEMBLY | R2: =IF('query (2)'!H2="","",TRIM(UPPER('query (2)'!H2))) -> AUTO BUSH PRESS MACHINE | S2: =IF('query (2)'!H2="","",'query (2)'!H2) -> Auto bush press machine | T2: =IF('query (2)'!J2="","",TRIM(UPPER('query (2)'!J2))) -> AUTO BUSH PRESS | U2: =IFERROR(IF(ISNUMBER(VALUE(MID($R2,SEARCH("(??-???)",$R2)+4,3))),MID($R2,SEARCH("(??-???)",$R2)+1,6),""),"") | V2: =IF('query (2)'!K2="","NOT_SPECIFIED",IFERROR(INDEX(Cleaning_Rules!$B$32:$B$34,MATCH(TRIM(UPPER('query (2)'!K2)),Cleaning_Rules!$A$32:$A$34,0)),"UNKNOWN")) -> NOT_SPECIFIED | W2: =_xlfn.TEXTJOIN(" | ",TRUE,$B2,$G2,$J2,$M2,$O2,$P2,$Q2,$R2,$T2,$V2) -> AS-955 | FACTORY3 | KWD5 | KWD | ASSEMBLY | 1016-KW5AI | ASSEMBLY | AUTO BUSH PRESS MACHINE | AUTO BUSH PRESS | NOT_SPECIFIED | X2: =_xlfn.TEXTJOIN("; ",TRUE,IF($B2="","MISSING_QR",""),IF(N($E2)>1,"DUPLICATE_QR",""),IF($F2="","MISSING_NO",""),IF($G2="UNKNOWN","MISSING_LOCATION",""),IF($J2="UNKNOWN","MISSING_DEPARTMENT",""),IF($N2="UNKNOWN","MISSING_SECTION",""),IF($O2="NOT_SPECIFIED","MISSING_RESPONSIBLE",""),IF($P2="","MISSING_COST_CENTER",""),IF($Q2="UNKNOWN","MISSING_CATEGORY",""),IF($R2="","MISSING_DESCRIPTION","")) | Y2: =_xlfn.TEXTJOIN("; ",TRUE,IF($V2="NOT_SPECIFIED","MISSING_STATUS",""),IF($Q2="OTHER","CATEGORY_NOT_USEFUL",""),IF($T2="","MISSING_PRODUCTION_NAME",""),IF($N2="DERIVED","SECTION_DERIVED","")) -> MISSING_STATUS
A3: =IF($B3="","NO_QR#"&TEXT(ROW()-1,"0000"),$B3&"#"&TEXT(ROW()-1,"0000")) -> AS-962#0002 | B3: =IF('query (2)'!B3="","",TRIM(UPPER('query (2)'!B3))) -> AS-962 | C3: =IF('query (2)'!B3="","",'query (2)'!B3) -> AS-962 | D3: =IF($B3="","",IFERROR(_xlfn.TEXTBEFORE($B3,"-"),"NO_PREFIX")) -> AS | E3: =IF($B3="","",COUNTIF($B$2:$B$974,$B3)) -> 1 | F3: =IF('query (2)'!A3="","",IFERROR(VALUE('query (2)'!A3),"")) -> 2 | G3: =IF('query (2)'!C3="","UNKNOWN",IFERROR(INDEX(Cleaning_Rules!$B$15:$B$20,MATCH(TRIM(UPPER('query (2)'!C3)),Cleaning_Rules!$A$15:$A$20,0)),"UNKNOWN")) -> FACTORY3 | H3: =IF('query (2)'!C3="","",'query (2)'!C3) -> FACTORY3 | I3: {=_xlfn.IFS($G3="UNKNOWN","UNKNOWN",OR($G3="FACTORY1",$G3="FACTORY2",$G3="FACTORY3"),"PLANT",TRUE,"SHARED")} -> PLANT | J3: =IF('query (2)'!D3="","UNKNOWN",IF(COUNTIF(Cleaning_Rules!$A$6:$A$11,TRIM('query (2)'!D3))>0,"UNKNOWN",IFERROR(INDEX(Cleaning_Rules!$B$24:$B$28,MATCH(TRIM(UPPER('query (2)'!D3)),Cleaning_Rules!$A$24:$A$28,0)),TRIM(UPPER('query (2)'!D3))))) -> KWD7 | K3: =IF('query (2)'!D3="","",'query (2)'!D3) -> KWD7 | L3: =IF($J3="UNKNOWN","",_xlfn.TEXTBEFORE($J3,{"0","1","2","3","4","5","6","7","8","9"," ","-","."},1,,,$J3)) -> KWD | M3: =IF('query (2)'!I3<>"",TRIM(UPPER('query (2)'!I3)),IF($L3="","UNKNOWN",$L3)) -> KWD | N3: =IF('query (2)'!I3<>"","SOURCE",IF($L3="","UNKNOWN","DERIVED")) -> SOURCE | O3: =IF('query (2)'!E3="","NOT_SPECIFIED",TRIM(UPPER('query (2)'!E3))) -> ASSEMBLY | P3: =IF('query (2)'!F3="","",TRIM(UPPER('query (2)'!F3))) -> 1025-KW7AI | Q3: =IF('query (2)'!G3="","UNKNOWN",IFERROR(INDEX(Cleaning_Rules!$B$38:$B$46,MATCH(TRIM(UPPER('query (2)'!G3)),Cleaning_Rules!$A$38:$A$46,0)),"UNKNOWN")) -> ASSEMBLY | R3: =IF('query (2)'!H3="","",TRIM(UPPER('query (2)'!H3))) -> AUTO BUSH PRESS MACHINE | S3: =IF('query (2)'!H3="","",'query (2)'!H3) -> Auto bush press machine | T3: =IF('query (2)'!J3="","",TRIM(UPPER('query (2)'!J3))) -> AUTO BUSH PRESS | U3: =IFERROR(IF(ISNUMBER(VALUE(MID($R3,SEARCH("(??-???)",$R3)+4,3))),MID($R3,SEARCH("(??-???)",$R3)+1,6),""),"") | V3: =IF('query (2)'!K3="","NOT_SPECIFIED",IFERROR(INDEX(Cleaning_Rules!$B$32:$B$34,MATCH(TRIM(UPPER('query (2)'!K3)),Cleaning_Rules!$A$32:$A$34,0)),"UNKNOWN")) -> NOT_SPECIFIED | W3: =_xlfn.TEXTJOIN(" | ",TRUE,$B3,$G3,$J3,$M3,$O3,$P3,$Q3,$R3,$T3,$V3) -> AS-962 | FACTORY3 | KWD7 | KWD | ASSEMBLY | 1025-KW7AI | ASSEMBLY | AUTO BUSH PRESS MACHINE | AUTO BUSH PRESS | NOT_SPECIFIED | X3: =_xlfn.TEXTJOIN("; ",TRUE,IF($B3="","MISSING_QR",""),IF(N($E3)>1,"DUPLICATE_QR",""),IF($F3="","MISSING_NO",""),IF($G3="UNKNOWN","MISSING_LOCATION",""),IF($J3="UNKNOWN","MISSING_DEPARTMENT",""),IF($N3="UNKNOWN","MISSING_SECTION",""),IF($O3="NOT_SPECIFIED","MISSING_RESPONSIBLE",""),IF($P3="","MISSING_COST_CENTER",""),IF($Q3="UNKNOWN","MISSING_CATEGORY",""),IF($R3="","MISSING_DESCRIPTION","")) | Y3: =_xlfn.TEXTJOIN("; ",TRUE,IF($V3="NOT_SPECIFIED","MISSING_STATUS",""),IF($Q3="OTHER","CATEGORY_NOT_USEFUL",""),IF($T3="","MISSING_PRODUCTION_NAME",""),IF($N3="DERIVED","SECTION_DERIVED","")) -> MISSING_STATUS
A4: =IF($B4="","NO_QR#"&TEXT(ROW()-1,"0000"),$B4&"#"&TEXT(ROW()-1,"0000")) -> AS-909#0003 | B4: =IF('query (2)'!B4="","",TRIM(UPPER('query (2)'!B4))) -> AS-909 | C4: =IF('query (2)'!B4="","",'query (2)'!B4) -> AS-909 | D4: =IF($B4="","",IFERROR(_xlfn.TEXTBEFORE($B4,"-"),"NO_PREFIX")) -> AS | E4: =IF($B4="","",COUNTIF($B$2:$B$974,$B4)) -> 1 | F4: =IF('query (2)'!A4="","",IFERROR(VALUE('query (2)'!A4),"")) -> 3 | G4: =IF('query (2)'!C4="","UNKNOWN",IFERROR(INDEX(Cleaning_Rules!$B$15:$B$20,MATCH(TRIM(UPPER('query (2)'!C4)),Cleaning_Rules!$A$15:$A$20,0)),"UNKNOWN")) -> FACTORY3 | H4: =IF('query (2)'!C4="","",'query (2)'!C4) -> FACTORY3 | I4: {=_xlfn.IFS($G4="UNKNOWN","UNKNOWN",OR($G4="FACTORY1",$G4="FACTORY2",$G4="FACTORY3"),"PLANT",TRUE,"SHARED")} -> PLANT | J4: =IF('query (2)'!D4="","UNKNOWN",IF(COUNTIF(Cleaning_Rules!$A$6:$A$11,TRIM('query (2)'!D4))>0,"UNKNOWN",IFERROR(INDEX(Cleaning_Rules!$B$24:$B$28,MATCH(TRIM(UPPER('query (2)'!D4)),Cleaning_Rules!$A$24:$A$28,0)),TRIM(UPPER('query (2)'!D4))))) -> KWD4 | K4: =IF('query (2)'!D4="","",'query (2)'!D4) -> KWD4 | L4: =IF($J4="UNKNOWN","",_xlfn.TEXTBEFORE($J4,{"0","1","2","3","4","5","6","7","8","9"," ","-","."},1,,,$J4)) -> KWD | M4: =IF('query (2)'!I4<>"",TRIM(UPPER('query (2)'!I4)),IF($L4="","UNKNOWN",$L4)) -> KWD | N4: =IF('query (2)'!I4<>"","SOURCE",IF($L4="","UNKNOWN","DERIVED")) -> SOURCE | O4: =IF('query (2)'!E4="","NOT_SPECIFIED",TRIM(UPPER('query (2)'!E4))) -> ASSEMBLY | P4: =IF('query (2)'!F4="","",TRIM(UPPER('query (2)'!F4))) -> 1013-KW4AI | Q4: =IF('query (2)'!G4="","UNKNOWN",IFERROR(INDEX(Cleaning_Rules!$B$38:$B$46,MATCH(TRIM(UPPER('query (2)'!G4)),Cleaning_Rules!$A$38:$A$46,0)),"UNKNOWN")) -> ASSEMBLY | R4: =IF('query (2)'!H4="","",TRIM(UPPER('query (2)'!H4))) -> AUTOMATIC ASSEMBLY MACHINE | S4: =IF('query (2)'!H4="","",'query (2)'!H4) -> Automatic assembly machine | T4: =IF('query (2)'!J4="","",TRIM(UPPER('query (2)'!J4))) -> AUTOMATIC ASSEMBLY | U4: =IFERROR(IF(ISNUMBER(VALUE(MID($R4,SEARCH("(??-???)",$R4)+4,3))),MID($R4,SEARCH("(??-???)",$R4)+1,6),""),"") | V4: =IF('query (2)'!K4="","NOT_SPECIFIED",IFERROR(INDEX(Cleaning_Rules!$B$32:$B$34,MATCH(TRIM(UPPER('query (2)'!K4)),Cleaning_Rules!$A$32:$A$34,0)),"UNKNOWN")) -> NOT_SPECIFIED | W4: =_xlfn.TEXTJOIN(" | ",TRUE,$B4,$G4,$J4,$M4,$O4,$P4,$Q4,$R4,$T4,$V4) -> AS-909 | FACTORY3 | KWD4 | KWD | ASSEMBLY | 1013-KW4AI | ASSEMBLY | AUTOMATIC ASSEMBLY MACHINE | AUTOMATIC ASSEMBLY | NOT_SPECIFIED | X4: =_xlfn.TEXTJOIN("; ",TRUE,IF($B4="","MISSING_QR",""),IF(N($E4)>1,"DUPLICATE_QR",""),IF($F4="","MISSING_NO",""),IF($G4="UNKNOWN","MISSING_LOCATION",""),IF($J4="UNKNOWN","MISSING_DEPARTMENT",""),IF($N4="UNKNOWN","MISSING_SECTION",""),IF($O4="NOT_SPECIFIED","MISSING_RESPONSIBLE",""),IF($P4="","MISSING_COST_CENTER",""),IF($Q4="UNKNOWN","MISSING_CATEGORY",""),IF($R4="","MISSING_DESCRIPTION","")) | Y4: =_xlfn.TEXTJOIN("; ",TRUE,IF($V4="NOT_SPECIFIED","MISSING_STATUS",""),IF($Q4="OTHER","CATEGORY_NOT_USEFUL",""),IF($T4="","MISSING_PRODUCTION_NAME",""),IF($N4="DERIVED","SECTION_DERIVED","")) -> MISSING_STATUS
A5: =IF($B5="","NO_QR#"&TEXT(ROW()-1,"0000"),$B5&"#"&TEXT(ROW()-1,"0000")) -> AS-956#0004 | B5: =IF('query (2)'!B5="","",TRIM(UPPER('query (2)'!B5))) -> AS-956 | C5: =IF('query (2)'!B5="","",'query (2)'!B5) -> AS-956 | D5: =IF($B5="","",IFERROR(_xlfn.TEXTBEFORE($B5,"-"),"NO_PREFIX")) -> AS | E5: =IF($B5="","",COUNTIF($B$2:$B$974,$B5)) -> 1 | F5: =IF('query (2)'!A5="","",IFERROR(VALUE('query (2)'!A5),"")) -> 4 | G5: =IF('query (2)'!C5="","UNKNOWN",IFERROR(INDEX(Cleaning_Rules!$B$15:$B$20,MATCH(TRIM(UPPER('query (2)'!C5)),Cleaning_Rules!$A$15:$A$20,0)),"UNKNOWN")) -> FACTORY3 | H5: =IF('query (2)'!C5="","",'query (2)'!C5) -> FACTORY3 | I5: {=_xlfn.IFS($G5="UNKNOWN","UNKNOWN",OR($G5="FACTORY1",$G5="FACTORY2",$G5="FACTORY3"),"PLANT",TRUE,"SHARED")} -> PLANT | J5: =IF('query (2)'!D5="","UNKNOWN",IF(COUNTIF(Cleaning_Rules!$A$6:$A$11,TRIM('query (2)'!D5))>0,"UNKNOWN",IFERROR(INDEX(Cleaning_Rules!$B$24:$B$28,MATCH(TRIM(UPPER('query (2)'!D5)),Cleaning_Rules!$A$24:$A$28,0)),TRIM(UPPER('query (2)'!D5))))) -> KWD1 | K5: =IF('query (2)'!D5="","",'query (2)'!D5) -> KWD1 | L5: =IF($J5="UNKNOWN","",_xlfn.TEXTBEFORE($J5,{"0","1","2","3","4","5","6","7","8","9"," ","-","."},1,,,$J5)) -> KWD | M5: =IF('query (2)'!I5<>"",TRIM(UPPER('query (2)'!I5)),IF($L5="","UNKNOWN",$L5)) -> KWD | N5: =IF('query (2)'!I5<>"","SOURCE",IF($L5="","UNKNOWN","DERIVED")) -> SOURCE | O5: =IF('query (2)'!E5="","NOT_SPECIFIED",TRIM(UPPER('query (2)'!E5))) -> ASSEMBLY | P5: =IF('query (2)'!F5="","",TRIM(UPPER('query (2)'!F5))) -> 1004-KW1AI | Q5: =IF('query (2)'!G5="","UNKNOWN",IFERROR(INDEX(Cleaning_Rules!$B$38:$B$46,MATCH(TRIM(UPPER('query (2)'!G5)),Cleaning_Rules!$A$38:$A$46,0)),"UNKNOWN")) -> ASSEMBLY | R5: =IF('query (2)'!H5="","",TRIM(UPPER('query (2)'!H5))) -> AUTOMATIC ASSEMBLY MACHINE | S5: =IF('query (2)'!H5="","",'query (2)'!H5) -> Automatic assembly machine | T5: =IF('query (2)'!J5="","",TRIM(UPPER('query (2)'!J5))) -> AUTOMATIC ASSEMBLY | U5: =IFERROR(IF(ISNUMBER(VALUE(MID($R5,SEARCH("(??-???)",$R5)+4,3))),MID($R5,SEARCH("(??-???)",$R5)+1,6),""),"") | V5: =IF('query (2)'!K5="","NOT_SPECIFIED",IFERROR(INDEX(Cleaning_Rules!$B$32:$B$34,MATCH(TRIM(UPPER('query (2)'!K5)),Cleaning_Rules!$A$32:$A$34,0)),"UNKNOWN")) -> NOT_SPECIFIED | W5: =_xlfn.TEXTJOIN(" | ",TRUE,$B5,$G5,$J5,$M5,$O5,$P5,$Q5,$R5,$T5,$V5) -> AS-956 | FACTORY3 | KWD1 | KWD | ASSEMBLY | 1004-KW1AI | ASSEMBLY | AUTOMATIC ASSEMBLY MACHINE | AUTOMATIC ASSEMBLY | NOT_SPECIFIED | X5: =_xlfn.TEXTJOIN("; ",TRUE,IF($B5="","MISSING_QR",""),IF(N($E5)>1,"DUPLICATE_QR",""),IF($F5="","MISSING_NO",""),IF($G5="UNKNOWN","MISSING_LOCATION",""),IF($J5="UNKNOWN","MISSING_DEPARTMENT",""),IF($N5="UNKNOWN","MISSING_SECTION",""),IF($O5="NOT_SPECIFIED","MISSING_RESPONSIBLE",""),IF($P5="","MISSING_COST_CENTER",""),IF($Q5="UNKNOWN","MISSING_CATEGORY",""),IF($R5="","MISSING_DESCRIPTION","")) | Y5: =_xlfn.TEXTJOIN("; ",TRUE,IF($V5="NOT_SPECIFIED","MISSING_STATUS",""),IF($Q5="OTHER","CATEGORY_NOT_USEFUL",""),IF($T5="","MISSING_PRODUCTION_NAME",""),IF($N5="DERIVED","SECTION_DERIVED","")) -> MISSING_STATUS
A6: =IF($B6="","NO_QR#"&TEXT(ROW()-1,"0000"),$B6&"#"&TEXT(ROW()-1,"0000")) -> AS-924#0005 | B6: =IF('query (2)'!B6="","",TRIM(UPPER('query (2)'!B6))) -> AS-924 | C6: =IF('query (2)'!B6="","",'query (2)'!B6) -> AS-924 | D6: =IF($B6="","",IFERROR(_xlfn.TEXTBEFORE($B6,"-"),"NO_PREFIX")) -> AS | E6: =IF($B6="","",COUNTIF($B$2:$B$974,$B6)) -> 1 | F6: =IF('query (2)'!A6="","",IFERROR(VALUE('query (2)'!A6),"")) -> 5 | G6: =IF('query (2)'!C6="","UNKNOWN",IFERROR(INDEX(Cleaning_Rules!$B$15:$B$20,MATCH(TRIM(UPPER('query (2)'!C6)),Cleaning_Rules!$A$15:$A$20,0)),"UNKNOWN")) -> FACTORY3 | H6: =IF('query (2)'!C6="","",'query (2)'!C6) -> FACTORY3 | I6: {=_xlfn.IFS($G6="UNKNOWN","UNKNOWN",OR($G6="FACTORY1",$G6="FACTORY2",$G6="FACTORY3"),"PLANT",TRUE,"SHARED")} -> PLANT | J6: =IF('query (2)'!D6="","UNKNOWN",IF(COUNTIF(Cleaning_Rules!$A$6:$A$11,TRIM('query (2)'!D6))>0,"UNKNOWN",IFERROR(INDEX(Cleaning_Rules!$B$24:$B$28,MATCH(TRIM(UPPER('query (2)'!D6)),Cleaning_Rules!$A$24:$A$28,0)),TRIM(UPPER('query (2)'!D6))))) -> KWD5 | K6: =IF('query (2)'!D6="","",'query (2)'!D6) -> KWD5 | L6: =IF($J6="UNKNOWN","",_xlfn.TEXTBEFORE($J6,{"0","1","2","3","4","5","6","7","8","9"," ","-","."},1,,,$J6)) -> KWD | M6: =IF('query (2)'!I6<>"",TRIM(UPPER('query (2)'!I6)),IF($L6="","UNKNOWN",$L6)) -> KWD | N6: =IF('query (2)'!I6<>"","SOURCE",IF($L6="","UNKNOWN","DERIVED")) -> SOURCE | O6: =IF('query (2)'!E6="","NOT_SPECIFIED",TRIM(UPPER('query (2)'!E6))) -> ASSEMBLY | P6: =IF('query (2)'!F6="","",TRIM(UPPER('query (2)'!F6))) -> 1016-KW5AI | Q6: =IF('query (2)'!G6="","UNKNOWN",IFERROR(INDEX(Cleaning_Rules!$B$38:$B$46,MATCH(TRIM(UPPER('query (2)'!G6)),Cleaning_Rules!$A$38:$A$46,0)),"UNKNOWN")) -> ASSEMBLY | R6: =IF('query (2)'!H6="","",TRIM(UPPER('query (2)'!H6))) -> AUTOMATIC ASSEMBLY MACHINE | S6: =IF('query (2)'!H6="","",'query (2)'!H6) -> Automatic assembly machine | T6: =IF('query (2)'!J6="","",TRIM(UPPER('query (2)'!J6))) -> AUTOMATIC ASSEMBLY | U6: =IFERROR(IF(ISNUMBER(VALUE(MID($R6,SEARCH("(??-???)",$R6)+4,3))),MID($R6,SEARCH("(??-???)",$R6)+1,6),""),"") | V6: =IF('query (2)'!K6="","NOT_SPECIFIED",IFERROR(INDEX(Cleaning_Rules!$B$32:$B$34,MATCH(TRIM(UPPER('query (2)'!K6)),Cleaning_Rules!$A$32:$A$34,0)),"UNKNOWN")) -> NOT_SPECIFIED | W6: =_xlfn.TEXTJOIN(" | ",TRUE,$B6,$G6,$J6,$M6,$O6,$P6,$Q6,$R6,$T6,$V6) -> AS-924 | FACTORY3 | KWD5 | KWD | ASSEMBLY | 1016-KW5AI | ASSEMBLY | AUTOMATIC ASSEMBLY MACHINE | AUTOMATIC ASSEMBLY | NOT_SPECIFIED | X6: =_xlfn.TEXTJOIN("; ",TRUE,IF($B6="","MISSING_QR",""),IF(N($E6)>1,"DUPLICATE_QR",""),IF($F6="","MISSING_NO",""),IF($G6="UNKNOWN","MISSING_LOCATION",""),IF($J6="UNKNOWN","MISSING_DEPARTMENT",""),IF($N6="UNKNOWN","MISSING_SECTION",""),IF($O6="NOT_SPECIFIED","MISSING_RESPONSIBLE",""),IF($P6="","MISSING_COST_CENTER",""),IF($Q6="UNKNOWN","MISSING_CATEGORY",""),IF($R6="","MISSING_DESCRIPTION","")) | Y6: =_xlfn.TEXTJOIN("; ",TRUE,IF($V6="NOT_SPECIFIED","MISSING_STATUS",""),IF($Q6="OTHER","CATEGORY_NOT_USEFUL",""),IF($T6="","MISSING_PRODUCTION_NAME",""),IF($N6="DERIVED","SECTION_DERIVED","")) -> MISSING_STATUS
A7: =IF($B7="","NO_QR#"&TEXT(ROW()-1,"0000"),$B7&"#"&TEXT(ROW()-1,"0000")) -> AS-700#0006 | B7: =IF('query (2)'!B7="","",TRIM(UPPER('query (2)'!B7))) -> AS-700 | C7: =IF('query (2)'!B7="","",'query (2)'!B7) -> AS-700 | D7: =IF($B7="","",IFERROR(_xlfn.TEXTBEFORE($B7,"-"),"NO_PREFIX")) -> AS | E7: =IF($B7="","",COUNTIF($B$2:$B$974,$B7)) -> 1 | F7: =IF('query (2)'!A7="","",IFERROR(VALUE('query (2)'!A7),"")) -> 6 | G7: =IF('query (2)'!C7="","UNKNOWN",IFERROR(INDEX(Cleaning_Rules!$B$15:$B$20,MATCH(TRIM(UPPER('query (2)'!C7)),Cleaning_Rules!$A$15:$A$20,0)),"UNKNOWN")) -> FACTORY3 | H7: =IF('query (2)'!C7="","",'query (2)'!C7) -> FACTORY3 | I7: {=_xlfn.IFS($G7="UNKNOWN","UNKNOWN",OR($G7="FACTORY1",$G7="FACTORY2",$G7="FACTORY3"),"PLANT",TRUE,"SHARED")} -> PLANT | J7: =IF('query (2)'!D7="","UNKNOWN",IF(COUNTIF(Cleaning_Rules!$A$6:$A$11,TRIM('query (2)'!D7))>0,"UNKNOWN",IFERROR(INDEX(Cleaning_Rules!$B$24:$B$28,MATCH(TRIM(UPPER('query (2)'!D7)),Cleaning_Rules!$A$24:$A$28,0)),TRIM(UPPER('query (2)'!D7))))) -> KWD6 | K7: =IF('query (2)'!D7="","",'query (2)'!D7) -> KWD6 | L7: =IF($J7="UNKNOWN","",_xlfn.TEXTBEFORE($J7,{"0","1","2","3","4","5","6","7","8","9"," ","-","."},1,,,$J7)) -> KWD | M7: =IF('query (2)'!I7<>"",TRIM(UPPER('query (2)'!I7)),IF($L7="","UNKNOWN",$L7)) -> KWD | N7: =IF('query (2)'!I7<>"","SOURCE",IF($L7="","UNKNOWN","DERIVED")) -> SOURCE | O7: =IF('query (2)'!E7="","NOT_SPECIFIED",TRIM(UPPER('query (2)'!E7))) -> ASSEMBLY | P7: =IF('query (2)'!F7="","",TRIM(UPPER('query (2)'!F7))) -> 1019-KW6AI | Q7: =IF('query (2)'!G7="","UNKNOWN",IFERROR(INDEX(Cleaning_Rules!$B$38:$B$46,MATCH(TRIM(UPPER('query (2)'!G7)),Cleaning_Rules!$A$38:$A$46,0)),"UNKNOWN")) -> ASSEMBLY | R7: =IF('query (2)'!H7="","",TRIM(UPPER('query (2)'!H7))) -> AUTOMATIC ASSEMBLY MACHINE | S7: =IF('query (2)'!H7="","",'query (2)'!H7) -> Automatic assembly machine | T7: =IF('query (2)'!J7="","",TRIM(UPPER('query (2)'!J7))) -> AUTOMATIC ASSEMBLY | U7: =IFERROR(IF(ISNUMBER(VALUE(MID($R7,SEARCH("(??-???)",$R7)+4,3))),MID($R7,SEARCH("(??-???)",$R7)+1,6),""),"") | V7: =IF('query (2)'!K7="","NOT_SPECIFIED",IFERROR(INDEX(Cleaning_Rules!$B$32:$B$34,MATCH(TRIM(UPPER('query (2)'!K7)),Cleaning_Rules!$A$32:$A$34,0)),"UNKNOWN")) -> NOT_SPECIFIED | W7: =_xlfn.TEXTJOIN(" | ",TRUE,$B7,$G7,$J7,$M7,$O7,$P7,$Q7,$R7,$T7,$V7) -> AS-700 | FACTORY3 | KWD6 | KWD | ASSEMBLY | 1019-KW6AI | ASSEMBLY | AUTOMATIC ASSEMBLY MACHINE | AUTOMATIC ASSEMBLY | NOT_SPECIFIED | X7: =_xlfn.TEXTJOIN("; ",TRUE,IF($B7="","MISSING_QR",""),IF(N($E7)>1,"DUPLICATE_QR",""),IF($F7="","MISSING_NO",""),IF($G7="UNKNOWN","MISSING_LOCATION",""),IF($J7="UNKNOWN","MISSING_DEPARTMENT",""),IF($N7="UNKNOWN","MISSING_SECTION",""),IF($O7="NOT_SPECIFIED","MISSING_RESPONSIBLE",""),IF($P7="","MISSING_COST_CENTER",""),IF($Q7="UNKNOWN","MISSING_CATEGORY",""),IF($R7="","MISSING_DESCRIPTION","")) | Y7: =_xlfn.TEXTJOIN("; ",TRUE,IF($V7="NOT_SPECIFIED","MISSING_STATUS",""),IF($Q7="OTHER","CATEGORY_NOT_USEFUL",""),IF($T7="","MISSING_PRODUCTION_NAME",""),IF($N7="DERIVED","SECTION_DERIVED","")) -> MISSING_STATUS
A8: =IF($B8="","NO_QR#"&TEXT(ROW()-1,"0000"),$B8&"#"&TEXT(ROW()-1,"0000")) -> AS-833#0007 | B8: =IF('query (2)'!B8="","",TRIM(UPPER('query (2)'!B8))) -> AS-833 | C8: =IF('query (2)'!B8="","",'query (2)'!B8) -> AS-833 | D8: =IF($B8="","",IFERROR(_xlfn.TEXTBEFORE($B8,"-"),"NO_PREFIX")) -> AS | E8: =IF($B8="","",COUNTIF($B$2:$B$974,$B8)) -> 1 | F8: =IF('query (2)'!A8="","",IFERROR(VALUE('query (2)'!A8),"")) -> 7 | G8: =IF('query (2)'!C8="","UNKNOWN",IFERROR(INDEX(Cleaning_Rules!$B$15:$B$20,MATCH(TRIM(UPPER('query (2)'!C8)),Cleaning_Rules!$A$15:$A$20,0)),"UNKNOWN")) -> FACTORY3 | H8: =IF('query (2)'!C8="","",'query (2)'!C8) -> FACTORY3 | I8: {=_xlfn.IFS($G8="UNKNOWN","UNKNOWN",OR($G8="FACTORY1",$G8="FACTORY2",$G8="FACTORY3"),"PLANT",TRUE,"SHARED")} -> PLANT | J8: =IF('query (2)'!D8="","UNKNOWN",IF(COUNTIF(Cleaning_Rules!$A$6:$A$11,TRIM('query (2)'!D8))>0,"UNKNOWN",IFERROR(INDEX(Cleaning_Rules!$B$24:$B$28,MATCH(TRIM(UPPER('query (2)'!D8)),Cleaning_Rules!$A$24:$A$28,0)),TRIM(UPPER('query (2)'!D8))))) -> KWD7 | K8: =IF('query (2)'!D8="","",'query (2)'!D8) -> KWD7 | L8: =IF($J8="UNKNOWN","",_xlfn.TEXTBEFORE($J8,{"0","1","2","3","4","5","6","7","8","9"," ","-","."},1,,,$J8)) -> KWD | M8: =IF('query (2)'!I8<>"",TRIM(UPPER('query (2)'!I8)),IF($L8="","UNKNOWN",$L8)) -> KWD | N8: =IF('query (2)'!I8<>"","SOURCE",IF($L8="","UNKNOWN","DERIVED")) -> SOURCE | O8: =IF('query (2)'!E8="","NOT_SPECIFIED",TRIM(UPPER('query (2)'!E8))) -> ASSEMBLY | P8: =IF('query (2)'!F8="","",TRIM(UPPER('query (2)'!F8))) -> 1025-KW7AI | Q8: =IF('query (2)'!G8="","UNKNOWN",IFERROR(INDEX(Cleaning_Rules!$B$38:$B$46,MATCH(TRIM(UPPER('query (2)'!G8)),Cleaning_Rules!$A$38:$A$46,0)),"UNKNOWN")) -> ASSEMBLY | R8: =IF('query (2)'!H8="","",TRIM(UPPER('query (2)'!H8))) -> AUTOMATIC ASSEMBLY MACHINE | S8: =IF('query (2)'!H8="","",'query (2)'!H8) -> Automatic assembly machine | T8: =IF('query (2)'!J8="","",TRIM(UPPER('query (2)'!J8))) -> AUTOMATIC ASSEMBLY | U8: =IFERROR(IF(ISNUMBER(VALUE(MID($R8,SEARCH("(??-???)",$R8)+4,3))),MID($R8,SEARCH("(??-???)",$R8)+1,6),""),"") | V8: =IF('query (2)'!K8="","NOT_SPECIFIED",IFERROR(INDEX(Cleaning_Rules!$B$32:$B$34,MATCH(TRIM(UPPER('query (2)'!K8)),Cleaning_Rules!$A$32:$A$34,0)),"UNKNOWN")) -> NOT_SPECIFIED | W8: =_xlfn.TEXTJOIN(" | ",TRUE,$B8,$G8,$J8,$M8,$O8,$P8,$Q8,$R8,$T8,$V8) -> AS-833 | FACTORY3 | KWD7 | KWD | ASSEMBLY | 1025-KW7AI | ASSEMBLY | AUTOMATIC ASSEMBLY MACHINE | AUTOMATIC ASSEMBLY | NOT_SPECIFIED | X8: =_xlfn.TEXTJOIN("; ",TRUE,IF($B8="","MISSING_QR",""),IF(N($E8)>1,"DUPLICATE_QR",""),IF($F8="","MISSING_NO",""),IF($G8="UNKNOWN","MISSING_LOCATION",""),IF($J8="UNKNOWN","MISSING_DEPARTMENT",""),IF($N8="UNKNOWN","MISSING_SECTION",""),IF($O8="NOT_SPECIFIED","MISSING_RESPONSIBLE",""),IF($P8="","MISSING_COST_CENTER",""),IF($Q8="UNKNOWN","MISSING_CATEGORY",""),IF($R8="","MISSING_DESCRIPTION","")) | Y8: =_xlfn.TEXTJOIN("; ",TRUE,IF($V8="NOT_SPECIFIED","MISSING_STATUS",""),IF($Q8="OTHER","CATEGORY_NOT_USEFUL",""),IF($T8="","MISSING_PRODUCTION_NAME",""),IF($N8="DERIVED","SECTION_DERIVED","")) -> MISSING_STATUS
A9: =IF($B9="","NO_QR#"&TEXT(ROW()-1,"0000"),$B9&"#"&TEXT(ROW()-1,"0000")) -> AS-950#0008 | B9: =IF('query (2)'!B9="","",TRIM(UPPER('query (2)'!B9))) -> AS-950 | C9: =IF('query (2)'!B9="","",'query (2)'!B9) -> AS-950 | D9: =IF($B9="","",IFERROR(_xlfn.TEXTBEFORE($B9,"-"),"NO_PREFIX")) -> AS | E9: =IF($B9="","",COUNTIF($B$2:$B$974,$B9)) -> 1 | F9: =IF('query (2)'!A9="","",IFERROR(VALUE('query (2)'!A9),"")) -> 8 | G9: =IF('query (2)'!C9="","UNKNOWN",IFERROR(INDEX(Cleaning_Rules!$B$15:$B$20,MATCH(TRIM(UPPER('query (2)'!C9)),Cleaning_Rules!$A$15:$A$20,0)),"UNKNOWN")) -> FACTORY3 | H9: =IF('query (2)'!C9="","",'query (2)'!C9) -> FACTORY3 | I9: {=_xlfn.IFS($G9="UNKNOWN","UNKNOWN",OR($G9="FACTORY1",$G9="FACTORY2",$G9="FACTORY3"),"PLANT",TRUE,"SHARED")} -> PLANT | J9: =IF('query (2)'!D9="","UNKNOWN",IF(COUNTIF(Cleaning_Rules!$A$6:$A$11,TRIM('query (2)'!D9))>0,"UNKNOWN",IFERROR(INDEX(Cleaning_Rules!$B$24:$B$28,MATCH(TRIM(UPPER('query (2)'!D9)),Cleaning_Rules!$A$24:$A$28,0)),TRIM(UPPER('query (2)'!D9))))) -> KWD3 | K9: =IF('query (2)'!D9="","",'query (2)'!D9) -> KWD3 | L9: =IF($J9="UNKNOWN","",_xlfn.TEXTBEFORE($J9,{"0","1","2","3","4","5","6","7","8","9"," ","-","."},1,,,$J9)) -> KWD | M9: =IF('query (2)'!I9<>"",TRIM(UPPER('query (2)'!I9)),IF($L9="","UNKNOWN",$L9)) -> KWD | N9: =IF('query (2)'!I9<>"","SOURCE",IF($L9="","UNKNOWN","DERIVED")) -> SOURCE | O9: =IF('query (2)'!E9="","NOT_SPECIFIED",TRIM(UPPER('query (2)'!E9))) -> ASSEMBLY | P9: =IF('query (2)'!F9="","",TRIM(UPPER('query (2)'!F9))) -> 1010-KW3AI | Q9: =IF('query (2)'!G9="","UNKNOWN",IFERROR(INDEX(Cleaning_Rules!$B$38:$B$46,MATCH(TRIM(UPPER('query (2)'!G9)),Cleaning_Rules!$A$38:$A$46,0)),"UNKNOWN")) -> ASSEMBLY | R9: =IF('query (2)'!H9="","",TRIM(UPPER('query (2)'!H9))) -> AUTOMATIC ASSEMBLY MACHINE | S9: =IF('query (2)'!H9="","",'query (2)'!H9) -> Automatic assembly machine | T9: =IF('query (2)'!J9="","",TRIM(UPPER('query (2)'!J9))) -> AUTOMATIC ASSEMBLY | U9: =IFERROR(IF(ISNUMBER(VALUE(MID($R9,SEARCH("(??-???)",$R9)+4,3))),MID($R9,SEARCH("(??-???)",$R9)+1,6),""),"") | V9: =IF('query (2)'!K9="","NOT_SPECIFIED",IFERROR(INDEX(Cleaning_Rules!$B$32:$B$34,MATCH(TRIM(UPPER('query (2)'!K9)),Cleaning_Rules!$A$32:$A$34,0)),"UNKNOWN")) -> NOT_SPECIFIED | W9: =_xlfn.TEXTJOIN(" | ",TRUE,$B9,$G9,$J9,$M9,$O9,$P9,$Q9,$R9,$T9,$V9) -> AS-950 | FACTORY3 | KWD3 | KWD | ASSEMBLY | 1010-KW3AI | ASSEMBLY | AUTOMATIC ASSEMBLY MACHINE | AUTOMATIC ASSEMBLY | NOT_SPECIFIED | X9: =_xlfn.TEXTJOIN("; ",TRUE,IF($B9="","MISSING_QR",""),IF(N($E9)>1,"DUPLICATE_QR",""),IF($F9="","MISSING_NO",""),IF($G9="UNKNOWN","MISSING_LOCATION",""),IF($J9="UNKNOWN","MISSING_DEPARTMENT",""),IF($N9="UNKNOWN","MISSING_SECTION",""),IF($O9="NOT_SPECIFIED","MISSING_RESPONSIBLE",""),IF($P9="","MISSING_COST_CENTER",""),IF($Q9="UNKNOWN","MISSING_CATEGORY",""),IF($R9="","MISSING_DESCRIPTION","")) | Y9: =_xlfn.TEXTJOIN("; ",TRUE,IF($V9="NOT_SPECIFIED","MISSING_STATUS",""),IF($Q9="OTHER","CATEGORY_NOT_USEFUL",""),IF($T9="","MISSING_PRODUCTION_NAME",""),IF($N9="DERIVED","SECTION_DERIVED","")) -> MISSING_STATUS
A10: =IF($B10="","NO_QR#"&TEXT(ROW()-1,"0000"),$B10&"#"&TEXT(ROW()-1,"0000")) -> AS-949#0009 | B10: =IF('query (2)'!B10="","",TRIM(UPPER('query (2)'!B10))) -> AS-949 | C10: =IF('query (2)'!B10="","",'query (2)'!B10) -> AS-949 | D10: =IF($B10="","",IFERROR(_xlfn.TEXTBEFORE($B10,"-"),"NO_PREFIX")) -> AS | E10: =IF($B10="","",COUNTIF($B$2:$B$974,$B10)) -> 1 | F10: =IF('query (2)'!A10="","",IFERROR(VALUE('query (2)'!A10),"")) -> 9 | G10: =IF('query (2)'!C10="","UNKNOWN",IFERROR(INDEX(Cleaning_Rules!$B$15:$B$20,MATCH(TRIM(UPPER('query (2)'!C10)),Cleaning_Rules!$A$15:$A$20,0)),"UNKNOWN")) -> FACTORY3 | H10: =IF('query (2)'!C10="","",'query (2)'!C10) -> FACTORY3 | I10: {=_xlfn.IFS($G10="UNKNOWN","UNKNOWN",OR($G10="FACTORY1",$G10="FACTORY2",$G10="FACTORY3"),"PLANT",TRUE,"SHARED")} -> PLANT | J10: =IF('query (2)'!D10="","UNKNOWN",IF(COUNTIF(Cleaning_Rules!$A$6:$A$11,TRIM('query (2)'!D10))>0,"UNKNOWN",IFERROR(INDEX(Cleaning_Rules!$B$24:$B$28,MATCH(TRIM(UPPER('query (2)'!D10)),Cleaning_Rules!$A$24:$A$28,0)),TRIM(UPPER('query (2)'!D10))))) -> KWD2 | K10: =IF('query (2)'!D10="","",'query (2)'!D10) -> KWD2 | L10: =IF($J10="UNKNOWN","",_xlfn.TEXTBEFORE($J10,{"0","1","2","3","4","5","6","7","8","9"," ","-","."},1,,,$J10)) -> KWD | M10: =IF('query (2)'!I10<>"",TRIM(UPPER('query (2)'!I10)),IF($L10="","UNKNOWN",$L10)) -> KWD | N10: =IF('query (2)'!I10<>"","SOURCE",IF($L10="","UNKNOWN","DERIVED")) -> SOURCE | O10: =IF('query (2)'!E10="","NOT_SPECIFIED",TRIM(UPPER('query (2)'!E10))) -> ASSEMBLY | P10: =IF('query (2)'!F10="","",TRIM(UPPER('query (2)'!F10))) -> 1007-KW2AI | Q10: =IF('query (2)'!G10="","UNKNOWN",IFERROR(INDEX(Cleaning_Rules!$B$38:$B$46,MATCH(TRIM(UPPER('query (2)'!G10)),Cleaning_Rules!$A$38:$A$46,0)),"UNKNOWN")) -> ASSEMBLY | R10: =IF('query (2)'!H10="","",TRIM(UPPER('query (2)'!H10))) -> AUTOMATIC ASSEMBLY MACHINE | S10: =IF('query (2)'!H10="","",'query (2)'!H10) -> Automatic assembly machine | T10: =IF('query (2)'!J10="","",TRIM(UPPER('query (2)'!J10))) -> AUTOMATIC ASSEMBLY | U10: =IFERROR(IF(ISNUMBER(VALUE(MID($R10,SEARCH("(??-???)",$R10)+4,3))),MID($R10,SEARCH("(??-???)",$R10)+1,6),""),"") | V10: =IF('query (2)'!K10="","NOT_SPECIFIED",IFERROR(INDEX(Cleaning_Rules!$B$32:$B$34,MATCH(TRIM(UPPER('query (2)'!K10)),Cleaning_Rules!$A$32:$A$34,0)),"UNKNOWN")) -> NOT_SPECIFIED | W10: =_xlfn.TEXTJOIN(" | ",TRUE,$B10,$G10,$J10,$M10,$O10,$P10,$Q10,$R10,$T10,$V10) -> AS-949 | FACTORY3 | KWD2 | KWD | ASSEMBLY | 1007-KW2AI | ASSEMBLY | AUTOMATIC ASSEMBLY MACHINE | AUTOMATIC ASSEMBLY | NOT_SPECIFIED | X10: =_xlfn.TEXTJOIN("; ",TRUE,IF($B10="","MISSING_QR",""),IF(N($E10)>1,"DUPLICATE_QR",""),IF($F10="","MISSING_NO",""),IF($G10="UNKNOWN","MISSING_LOCATION",""),IF($J10="UNKNOWN","MISSING_DEPARTMENT",""),IF($N10="UNKNOWN","MISSING_SECTION",""),IF($O10="NOT_SPECIFIED","MISSING_RESPONSIBLE",""),IF($P10="","MISSING_COST_CENTER",""),IF($Q10="UNKNOWN","MISSING_CATEGORY",""),IF($R10="","MISSING_DESCRIPTION","")) | Y10: =_xlfn.TEXTJOIN("; ",TRUE,IF($V10="NOT_SPECIFIED","MISSING_STATUS",""),IF($Q10="OTHER","CATEGORY_NOT_USEFUL",""),IF($T10="","MISSING_PRODUCTION_NAME",""),IF($N10="DERIVED","SECTION_DERIVED","")) -> MISSING_STATUS
A11: =IF($B11="","NO_QR#"&TEXT(ROW()-1,"0000"),$B11&"#"&TEXT(ROW()-1,"0000")) -> CH-014#0010 | B11: =IF('query (2)'!B11="","",TRIM(UPPER('query (2)'!B11))) -> CH-014 | C11: =IF('query (2)'!B11="","",'query (2)'!B11) -> CH-014 | D11: =IF($B11="","",IFERROR(_xlfn.TEXTBEFORE($B11,"-"),"NO_PREFIX")) -> CH | E11: =IF($B11="","",COUNTIF($B$2:$B$974,$B11)) -> 1 | F11: =IF('query (2)'!A11="","",IFERROR(VALUE('query (2)'!A11),"")) -> 10 | G11: =IF('query (2)'!C11="","UNKNOWN",IFERROR(INDEX(Cleaning_Rules!$B$15:$B$20,MATCH(TRIM(UPPER('query (2)'!C11)),Cleaning_Rules!$A$15:$A$20,0)),"UNKNOWN")) -> FACTORY3 | H11: =IF('query (2)'!C11="","",'query (2)'!C11) -> FACTORY3 | I11: {=_xlfn.IFS($G11="UNKNOWN","UNKNOWN",OR($G11="FACTORY1",$G11="FACTORY2",$G11="FACTORY3"),"PLANT",TRUE,"SHARED")} -> PLANT | J11: =IF('query (2)'!D11="","UNKNOWN",IF(COUNTIF(Cleaning_Rules!$A$6:$A$11,TRIM('query (2)'!D11))>0,"UNKNOWN",IFERROR(INDEX(Cleaning_Rules!$B$24:$B$28,MATCH(TRIM(UPPER('query (2)'!D11)),Cleaning_Rules!$A$24:$A$28,0)),TRIM(UPPER('query (2)'!D11))))) -> KWD1 | K11: =IF('query (2)'!D11="","",'query (2)'!D11) -> KWD1 | L11: =IF($J11="UNKNOWN","",_xlfn.TEXTBEFORE($J11,{"0","1","2","3","4","5","6","7","8","9"," ","-","."},1,,,$J11)) -> KWD | M11: =IF('query (2)'!I11<>"",TRIM(UPPER('query (2)'!I11)),IF($L11="","UNKNOWN",$L11)) -> KWD | N11: =IF('query (2)'!I11<>"","SOURCE",IF($L11="","UNKNOWN","DERIVED")) -> SOURCE | O11: =IF('query (2)'!E11="","NOT_SPECIFIED",TRIM(UPPER('query (2)'!E11))) -> ASSEMBLY | P11: =IF('query (2)'!F11="","",TRIM(UPPER('query (2)'!F11))) -> 1004-KW1AI | Q11: =IF('query (2)'!G11="","UNKNOWN",IFERROR(INDEX(Cleaning_Rules!$B$38:$B$46,MATCH(TRIM(UPPER('query (2)'!G11)),Cleaning_Rules!$A$38:$A$46,0)),"UNKNOWN")) -> CHECK | R11: =IF('query (2)'!H11="","",TRIM(UPPER('query (2)'!H11))) -> AUTOMATION VIBRATION TESTING MACHINE | S11: =IF('query (2)'!H11="","",'query (2)'!H11) -> Automation vibration testing machine | T11: =IF('query (2)'!J11="","",TRIM(UPPER('query (2)'!J11))) -> NOISE INSPECTION AUTO | U11: =IFERROR(IF(ISNUMBER(VALUE(MID($R11,SEARCH("(??-???)",$R11)+4,3))),MID($R11,SEARCH("(??-???)",$R11)+1,6),""),"") | V11: =IF('query (2)'!K11="","NOT_SPECIFIED",IFERROR(INDEX(Cleaning_Rules!$B$32:$B$34,MATCH(TRIM(UPPER('query (2)'!K11)),Cleaning_Rules!$A$32:$A$34,0)),"UNKNOWN")) -> NOT_SPECIFIED | W11: =_xlfn.TEXTJOIN(" | ",TRUE,$B11,$G11,$J11,$M11,$O11,$P11,$Q11,$R11,$T11,$V11) -> CH-014 | FACTORY3 | KWD1 | KWD | ASSEMBLY | 1004-KW1AI | CHECK | AUTOMATION VIBRATION TESTING MACHINE | NOISE INSPECTION AUTO | NOT_SPECIFIED | X11: =_xlfn.TEXTJOIN("; ",TRUE,IF($B11="","MISSING_QR",""),IF(N($E11)>1,"DUPLICATE_QR",""),IF($F11="","MISSING_NO",""),IF($G11="UNKNOWN","MISSING_LOCATION",""),IF($J11="UNKNOWN","MISSING_DEPARTMENT",""),IF($N11="UNKNOWN","MISSING_SECTION",""),IF($O11="NOT_SPECIFIED","MISSING_RESPONSIBLE",""),IF($P11="","MISSING_COST_CENTER",""),IF($Q11="UNKNOWN","MISSING_CATEGORY",""),IF($R11="","MISSING_DESCRIPTION","")) | Y11: =_xlfn.TEXTJOIN("; ",TRUE,IF($V11="NOT_SPECIFIED","MISSING_STATUS",""),IF($Q11="OTHER","CATEGORY_NOT_USEFUL",""),IF($T11="","MISSING_PRODUCTION_NAME",""),IF($N11="DERIVED","SECTION_DERIVED","")) -> MISSING_STATUS
A12: =IF($B12="","NO_QR#"&TEXT(ROW()-1,"0000"),$B12&"#"&TEXT(ROW()-1,"0000")) -> CH-263#0011 | B12: =IF('query (2)'!B12="","",TRIM(UPPER('query (2)'!B12))) -> CH-263 | C12: =IF('query (2)'!B12="","",'query (2)'!B12) -> CH-263 | D12: =IF($B12="","",IFERROR(_xlfn.TEXTBEFORE($B12,"-"),"NO_PREFIX")) -> CH | E12: =IF($B12="","",COUNTIF($B$2:$B$974,$B12)) -> 1 | F12: =IF('query (2)'!A12="","",IFERROR(VALUE('query (2)'!A12),"")) -> 11 | G12: =IF('query (2)'!C12="","UNKNOWN",IFERROR(INDEX(Cleaning_Rules!$B$15:$B$20,MATCH(TRIM(UPPER('query (2)'!C12)),Cleaning_Rules!$A$15:$A$20,0)),"UNKNOWN")) -> FACTORY3 | H12: =IF('query (2)'!C12="","",'query (2)'!C12) -> FACTORY3 | I12: {=_xlfn.IFS($G12="UNKNOWN","UNKNOWN",OR($G12="FACTORY1",$G12="FACTORY2",$G12="FACTORY3"),"PLANT",TRUE,"SHARED")} -> PLANT | J12: =IF('query (2)'!D12="","UNKNOWN",IF(COUNTIF(Cleaning_Rules!$A$6:$A$11,TRIM('query (2)'!D12))>0,"UNKNOWN",IFERROR(INDEX(Cleaning_Rules!$B$24:$B$28,MATCH(TRIM(UPPER('query (2)'!D12)),Cleaning_Rules!$A$24:$A$28,0)),TRIM(UPPER('query (2)'!D12))))) -> KWD2 | K12: =IF('query (2)'!D12="","",'query (2)'!D12) -> KWD2 | L12: =IF($J12="UNKNOWN","",_xlfn.TEXTBEFORE($J12,{"0","1","2","3","4","5","6","7","8","9"," ","-","."},1,,,$J12)) -> KWD | M12: =IF('query (2)'!I12<>"",TRIM(UPPER('query (2)'!I12)),IF($L12="","UNKNOWN",$L12)) -> KWD | N12: =IF('query (2)'!I12<>"","SOURCE",IF($L12="","UNKNOWN","DERIVED")) -> SOURCE | O12: =IF('query (2)'!E12="","NOT_SPECIFIED",TRIM(UPPER('query (2)'!E12))) -> ASSEMBLY | P12: =IF('query (2)'!F12="","",TRIM(UPPER('query (2)'!F12))) -> 1007-KW2AI | Q12: =IF('query (2)'!G12="","UNKNOWN",IFERROR(INDEX(Cleaning_Rules!$B$38:$B$46,MATCH(TRIM(UPPER('query (2)'!G12)),Cleaning_Rules!$A$38:$A$46,0)),"UNKNOWN")) -> CHECK | R12: =IF('query (2)'!H12="","",TRIM(UPPER('query (2)'!H12))) -> AUTOMATION VIBRATION TESTING MACHINE | S12: =IF('query (2)'!H12="","",'query (2)'!H12) -> Automation vibration testing machine | T12: =IF('query (2)'!J12="","",TRIM(UPPER('query (2)'!J12))) -> NOISE INSPECTION AUTO | U12: =IFERROR(IF(ISNUMBER(VALUE(MID($R12,SEARCH("(??-???)",$R12)+4,3))),MID($R12,SEARCH("(??-???)",$R12)+1,6),""),"") | V12: =IF('query (2)'!K12="","NOT_SPECIFIED",IFERROR(INDEX(Cleaning_Rules!$B$32:$B$34,MATCH(TRIM(UPPER('query (2)'!K12)),Cleaning_Rules!$A$32:$A$34,0)),"UNKNOWN")) -> NOT_SPECIFIED | W12: =_xlfn.TEXTJOIN(" | ",TRUE,$B12,$G12,$J12,$M12,$O12,$P12,$Q12,$R12,$T12,$V12) -> CH-263 | FACTORY3 | KWD2 | KWD | ASSEMBLY | 1007-KW2AI | CHECK | AUTOMATION VIBRATION TESTING MACHINE | NOISE INSPECTION AUTO | NOT_SPECIFIED | X12: =_xlfn.TEXTJOIN("; ",TRUE,IF($B12="","MISSING_QR",""),IF(N($E12)>1,"DUPLICATE_QR",""),IF($F12="","MISSING_NO",""),IF($G12="UNKNOWN","MISSING_LOCATION",""),IF($J12="UNKNOWN","MISSING_DEPARTMENT",""),IF($N12="UNKNOWN","MISSING_SECTION",""),IF($O12="NOT_SPECIFIED","MISSING_RESPONSIBLE",""),IF($P12="","MISSING_COST_CENTER",""),IF($Q12="UNKNOWN","MISSING_CATEGORY",""),IF($R12="","MISSING_DESCRIPTION","")) | Y12: =_xlfn.TEXTJOIN("; ",TRUE,IF($V12="NOT_SPECIFIED","MISSING_STATUS",""),IF($Q12="OTHER","CATEGORY_NOT_USEFUL",""),IF($T12="","MISSING_PRODUCTION_NAME",""),IF($N12="DERIVED","SECTION_DERIVED","")) -> MISSING_STATUS
A13: =IF($B13="","NO_QR#"&TEXT(ROW()-1,"0000"),$B13&"#"&TEXT(ROW()-1,"0000")) -> CH-349#0012 | B13: =IF('query (2)'!B13="","",TRIM(UPPER('query (2)'!B13))) -> CH-349 | C13: =IF('query (2)'!B13="","",'query (2)'!B13) -> CH-349 | D13: =IF($B13="","",IFERROR(_xlfn.TEXTBEFORE($B13,"-"),"NO_PREFIX")) -> CH | E13: =IF($B13="","",COUNTIF($B$2:$B$974,$B13)) -> 1 | F13: =IF('query (2)'!A13="","",IFERROR(VALUE('query (2)'!A13),"")) -> 12 | G13: =IF('query (2)'!C13="","UNKNOWN",IFERROR(INDEX(Cleaning_Rules!$B$15:$B$20,MATCH(TRIM(UPPER('query (2)'!C13)),Cleaning_Rules!$A$15:$A$20,0)),"UNKNOWN")) -> FACTORY3 | H13: =IF('query (2)'!C13="","",'query (2)'!C13) -> FACTORY3 | I13: {=_xlfn.IFS($G13="UNKNOWN","UNKNOWN",OR($G13="FACTORY1",$G13="FACTORY2",$G13="FACTORY3"),"PLANT",TRUE,"SHARED")} -> PLANT | J13: =IF('query (2)'!D13="","UNKNOWN",IF(COUNTIF(Cleaning_Rules!$A$6:$A$11,TRIM('query (2)'!D13))>0,"UNKNOWN",IFERROR(INDEX(Cleaning_Rules!$B$24:$B$28,MATCH(TRIM(UPPER('query (2)'!D13)),Cleaning_Rules!$A$24:$A$28,0)),TRIM(UPPER('query (2)'!D13))))) -> KWD3 | K13: =IF('query (2)'!D13="","",'query (2)'!D13) -> KWD3 | L13: =IF($J13="UNKNOWN","",_xlfn.TEXTBEFORE($J13,{"0","1","2","3","4","5","6","7","8","9"," ","-","."},1,,,$J13)) -> KWD | M13: =IF('query (2)'!I13<>"",TRIM(UPPER('query (2)'!I13)),IF($L13="","UNKNOWN",$L13)) -> KWD | N13: =IF('query (2)'!I13<>"","SOURCE",IF($L13="","UNKNOWN","DERIVED")) -> SOURCE | O13: =IF('query (2)'!E13="","NOT_SPECIFIED",TRIM(UPPER('query (2)'!E13))) -> ASSEMBLY | P13: =IF('query (2)'!F13="","",TRIM(UPPER('query (2)'!F13))) -> 1010-KW3AI | Q13: =IF('query (2)'!G13="","UNKNOWN",IFERROR(INDEX(Cleaning_Rules!$B$38:$B$46,MATCH(TRIM(UPPER('query (2)'!G13)),Cleaning_Rules!$A$38:$A$46,0)),"UNKNOWN")) -> CHECK | R13: =IF('query (2)'!H13="","",TRIM(UPPER('query (2)'!H13))) -> AUTOMATION VIBRATION TESTING MACHINE | S13: =IF('query (2)'!H13="","",'query (2)'!H13) -> Automation vibration testing machine | T13: =IF('query (2)'!J13="","",TRIM(UPPER('query (2)'!J13))) -> NOISE INSPECTION AUTO | U13: =IFERROR(IF(ISNUMBER(VALUE(MID($R13,SEARCH("(??-???)",$R13)+4,3))),MID($R13,SEARCH("(??-???)",$R13)+1,6),""),"") | V13: =IF('query (2)'!K13="","NOT_SPECIFIED",IFERROR(INDEX(Cleaning_Rules!$B$32:$B$34,MATCH(TRIM(UPPER('query (2)'!K13)),Cleaning_Rules!$A$32:$A$34,0)),"UNKNOWN")) -> NOT_SPECIFIED | W13: =_xlfn.TEXTJOIN(" | ",TRUE,$B13,$G13,$J13,$M13,$O13,$P13,$Q13,$R13,$T13,$V13) -> CH-349 | FACTORY3 | KWD3 | KWD | ASSEMBLY | 1010-KW3AI | CHECK | AUTOMATION VIBRATION TESTING MACHINE | NOISE INSPECTION AUTO | NOT_SPECIFIED | X13: =_xlfn.TEXTJOIN("; ",TRUE,IF($B13="","MISSING_QR",""),IF(N($E13)>1,"DUPLICATE_QR",""),IF($F13="","MISSING_NO",""),IF($G13="UNKNOWN","MISSING_LOCATION",""),IF($J13="UNKNOWN","MISSING_DEPARTMENT",""),IF($N13="UNKNOWN","MISSING_SECTION",""),IF($O13="NOT_SPECIFIED","MISSING_RESPONSIBLE",""),IF($P13="","MISSING_COST_CENTER",""),IF($Q13="UNKNOWN","MISSING_CATEGORY",""),IF($R13="","MISSING_DESCRIPTION","")) | Y13: =_xlfn.TEXTJOIN("; ",TRUE,IF($V13="NOT_SPECIFIED","MISSING_STATUS",""),IF($Q13="OTHER","CATEGORY_NOT_USEFUL",""),IF($T13="","MISSING_PRODUCTION_NAME",""),IF($N13="DERIVED","SECTION_DERIVED","")) -> MISSING_STATUS
... A974: =IF($B974="","NO_QR#"&TEXT(ROW()-1,"0000"),$B974&"#"&TEXT(ROW()-1,"0000")) -> CTO-002#0973 | B974: =IF('query (2)'!B974="","",TRIM(UPPER('query (2)'!B974))) -> CTO-002 | C974: =IF('query (2)'!B974="","",'query (2)'!B974) -> CTO-002 | D974: =IF($B974="","",IFERROR(_xlfn.TEXTBEFORE($B974,"-"),"NO_PREFIX")) -> CTO | E974: =IF($B974="","",COUNTIF($B$2:$B$974,$B974)) -> 1 | F974: =IF('query (2)'!A974="","",IFERROR(VALUE('query (2)'!A974),"")) | G974: =IF('query (2)'!C974="","UNKNOWN",IFERROR(INDEX(Cleaning_Rules!$B$15:$B$20,MATCH(TRIM(UPPER('query (2)'!C974)),Cleaning_Rules!$A$15:$A$20,0)),"UNKNOWN")) -> UTILITY | H974: =IF('query (2)'!C974="","",'query (2)'!C974) -> UTILITY | I974: {=_xlfn.IFS($G974="UNKNOWN","UNKNOWN",OR($G974="FACTORY1",$G974="FACTORY2",$G974="FACTORY3"),"PLANT",TRUE,"SHARED")} -> SHARED | J974: =IF('query (2)'!D974="","UNKNOWN",IF(COUNTIF(Cleaning_Rules!$A$6:$A$11,TRIM('query (2)'!D974))>0,"UNKNOWN",IFERROR(INDEX(Cleaning_Rules!$B$24:$B$28,MATCH(TRIM(UPPER('query (2)'!D974)),Cleaning_Rules!$A$24:$A$28,0)),TRIM(UPPER('query (2)'!D974))))) -> UT | K974: =IF('query (2)'!D974="","",'query (2)'!D974) -> UT | L974: =IF($J974="UNKNOWN","",_xlfn.TEXTBEFORE($J974,{"0","1","2","3","4","5","6","7","8","9"," ","-","."},1,,,$J974)) -> UT | M974: =IF('query (2)'!I974<>"",TRIM(UPPER('query (2)'!I974)),IF($L974="","UNKNOWN",$L974)) -> UT | N974: =IF('query (2)'!I974<>"","SOURCE",IF($L974="","UNKNOWN","DERIVED")) -> DERIVED | O974: =IF('query (2)'!E974="","NOT_SPECIFIED",TRIM(UPPER('query (2)'!E974))) -> NOT_SPECIFIED | P974: =IF('query (2)'!F974="","",TRIM(UPPER('query (2)'!F974))) | Q974: =IF('query (2)'!G974="","UNKNOWN",IFERROR(INDEX(Cleaning_Rules!$B$38:$B$46,MATCH(TRIM(UPPER('query (2)'!G974)),Cleaning_Rules!$A$38:$A$46,0)),"UNKNOWN")) -> OTHER | R974: =IF('query (2)'!H974="","",TRIM(UPPER('query (2)'!H974))) -> CENTRAL OIL NO.3 | S974: =IF('query (2)'!H974="","",'query (2)'!H974) -> Central OIL NO.3 | T974: =IF('query (2)'!J974="","",TRIM(UPPER('query (2)'!J974))) | U974: =IFERROR(IF(ISNUMBER(VALUE(MID($R974,SEARCH("(??-???)",$R974)+4,3))),MID($R974,SEARCH("(??-???)",$R974)+1,6),""),"") | V974: =IF('query (2)'!K974="","NOT_SPECIFIED",IFERROR(INDEX(Cleaning_Rules!$B$32:$B$34,MATCH(TRIM(UPPER('query (2)'!K974)),Cleaning_Rules!$A$32:$A$34,0)),"UNKNOWN")) -> NEW | W974: =_xlfn.TEXTJOIN(" | ",TRUE,$B974,$G974,$J974,$M974,$O974,$P974,$Q974,$R974,$T974,$V974) -> CTO-002 | UTILITY | UT | UT | NOT_SPECIFIED | OTHER | CENTRAL OIL NO.3 | NEW | X974: =_xlfn.TEXTJOIN("; ",TRUE,IF($B974="","MISSING_QR",""),IF(N($E974)>1,"DUPLICATE_QR",""),IF($F974="","MISSING_NO",""),IF($G974="UNKNOWN","MISSING_LOCATION",""),IF($J974="UNKNOWN","MISSING_DEPARTMENT",""),IF($N974="UNKNOWN","MISSING_SECTION",""),IF($O974="NOT_SPECIFIED","MISSING_RESPONSIBLE",""),IF($P974="","MISSING_COST_CENTER",""),IF($Q974="UNKNOWN","MISSING_CATEGORY",""),IF($R974="","MISSING_DESCRIPTION","")) -> MISSING_NO; MISSING_RESPONSIBLE; MISSING_COST_CENTER | Y974: =_xlfn.TEXTJOIN("; ",TRUE,IF($V974="NOT_SPECIFIED","MISSING_STATUS",""),IF($Q974="OTHER","CATEGORY_NOT_USEFUL",""),IF($T974="","MISSING_PRODUCTION_NAME",""),IF($N974="DERIVED","SECTION_DERIVED","")) -> CATEGORY_NOT_USEFUL; MISSING_PRODUCTION_NAME; SECTION_DERIVED

Sheet Data_Readiness
A1: รายงานความพร้อมของข้อมูล / Data Readiness Report
A2: แหล่งข้อมูล: ชีต 'query (2)' ตาราง Table_query__2 — สแกนทุกแถว ไม่ได้สุ่มตัวอย่าง
A4: 1. ภาพรวม / Overview
A5: จำนวนแถวข้อมูล (Rows) | B5: =ROWS(Table_query__2[]) -> 973
A6: จำนวนคอลัมน์ (Columns) | B6: =COLUMNS(Table_query__2[]) -> 13
A7: QR_Code_List ที่ไม่ว่าง (non-blank) | B7: =COUNTA(Table_query__2[QR_Code_List]) -> 971
A8: QR_Code_List ที่ไม่ซ้ำ (unique) | B8: {=SUMPRODUCT((Table_query__2[QR_Code_List]<>"")/COUNTIF(Table_query__2[QR_Code_List],Table_query__2[QR_Code_List]&""))} -> 968
A9: รหัสที่ซ้ำ (duplicate codes) | B9: =B7-B8 -> 3 | C9: CH-523, MA-635, CH-093 (แต่ละรหัสปรากฏ 2 ครั้ง)
A10: แถวที่มีอักษรไทย (Thai script) | B10: 829
A11: คอลัมน์ตัวเลขสำหรับหายอดรวมธุรกิจ | B11: 0 | C11: ไม่มีคอลัมน์ตัวเลขจริงเลย → ทำ tie-out ยอดรวมไม่ได้ วิเคราะห์ได้แค่การนับ
A13: 2. โปรไฟล์รายคอลัมน์ / Per-column profile
A14: คอลัมน์ | B14: มีค่า | C14: ว่าง | D14: % ความสมบูรณ์ | E14: ค่าที่ต่างกัน | F14: สรุป | G14: เหตุผล / สิ่งที่พบ
A15: No | B15: =COUNTA(INDEX(Table_query__2[],0,MATCH($A15,Table_query__2[#Headers],0))) -> 887 | C15: =$B$5-B15 -> 86 | D15: =B15/$B$5 -> 0.91161357 | E15: {=SUMPRODUCT((INDEX(Table_query__2[],0,MATCH($A15,Table_query__2[#Headers],0))<>"")/COUNTIF(INDEX(Table_query__2[],0,MATCH($A15,Table_query__2[#Headers],0)),INDEX(Table_query__2[],0,MATCH($A15,Table_query__2[#Headers],0))&""))} -> 887 | F15: ⚠️ | G15: เลขรันที่เก็บเป็น "ข้อความ" ทั้งหมด (887 เซลล์) + ว่าง 86 แถว → เรียง/กรองตัวเลขไม่ได้ ใช้เป็น key ไม่ได้
A16: QR_Code_List | B16: =COUNTA(INDEX(Table_query__2[],0,MATCH($A16,Table_query__2[#Headers],0))) -> 971 | C16: =$B$5-B16 -> 2 | D16: =B16/$B$5 -> 0.9979445 | E16: {=SUMPRODUCT((INDEX(Table_query__2[],0,MATCH($A16,Table_query__2[#Headers],0))<>"")/COUNTIF(INDEX(Table_query__2[],0,MATCH($A16,Table_query__2[#Headers],0)),INDEX(Table_query__2[],0,MATCH($A16,Table_query__2[#Headers],0))&""))} -> 968 | F16: ⚠️ | G16: คอลัมน์ที่เหมาะเป็น key มากที่สุด แต่มีซ้ำ 3 รหัส (6 แถว) และว่าง 2 แถว; 4 แถวไม่มี prefix หมวดหมู่
A17: Location_List | B17: =COUNTA(INDEX(Table_query__2[],0,MATCH($A17,Table_query__2[#Headers],0))) -> 971 | C17: =$B$5-B17 -> 2 | D17: =B17/$B$5 -> 0.9979445 | E17: {=SUMPRODUCT((INDEX(Table_query__2[],0,MATCH($A17,Table_query__2[#Headers],0))<>"")/COUNTIF(INDEX(Table_query__2[],0,MATCH($A17,Table_query__2[#Headers],0)),INDEX(Table_query__2[],0,MATCH($A17,Table_query__2[#Headers],0))&""))} -> 8 | F17: ⚠️ | G17: มี 5 ค่าจริง (FACTORY1/2/3, ALL FACTORY, UTILITY, TOOLING) แต่มีค่าขยะ "-" 2 แถว และ "." 1 แถว
A18: Department_List | B18: =COUNTA(INDEX(Table_query__2[],0,MATCH($A18,Table_query__2[#Headers],0))) -> 968 | C18: =$B$5-B18 -> 5 | D18: =B18/$B$5 -> 0.99486125 | E18: {=SUMPRODUCT((INDEX(Table_query__2[],0,MATCH($A18,Table_query__2[#Headers],0))<>"")/COUNTIF(INDEX(Table_query__2[],0,MATCH($A18,Table_query__2[#Headers],0)),INDEX(Table_query__2[],0,MATCH($A18,Table_query__2[#Headers],0))&""))} -> 53 | F18: ⚠️ | G18: 53 ค่า ตั้งชื่อไม่มีมาตรฐาน (HUB2.5 vs HUB3-1, "NB Assambly1" สะกดผิด, "TOOL Shop"/"Tooling Engineer") + ค่าขยะ "." 1 แถว
A19: RESPONSIBLE | B19: =COUNTA(INDEX(Table_query__2[],0,MATCH($A19,Table_query__2[#Headers],0))) -> 904 | C19: =$B$5-B19 -> 69 | D19: =B19/$B$5 -> 0.9290853 | E19: {=SUMPRODUCT((INDEX(Table_query__2[],0,MATCH($A19,Table_query__2[#Headers],0))<>"")/COUNTIF(INDEX(Table_query__2[],0,MATCH($A19,Table_query__2[#Headers],0)),INDEX(Table_query__2[],0,MATCH($A19,Table_query__2[#Headers],0))&""))} -> 3 | F19: ❌ | G19: มีเพียง 3 ค่า (Assembly 508, Grinding 2 358, Grinding 1 38) ว่าง 69 แถว — เป็นกลุ่มงาน ไม่ใช่ชื่อผู้รับผิดชอบ → ตอบคำถาม "ใครดูแลเครื่องนี้" ไม่ได้
A20: Cost_Center | B20: =COUNTA(INDEX(Table_query__2[],0,MATCH($A20,Table_query__2[#Headers],0))) -> 911 | C20: =$B$5-B20 -> 62 | D20: =B20/$B$5 -> 0.93627955 | E20: {=SUMPRODUCT((INDEX(Table_query__2[],0,MATCH($A20,Table_query__2[#Headers],0))<>"")/COUNTIF(INDEX(Table_query__2[],0,MATCH($A20,Table_query__2[#Headers],0)),INDEX(Table_query__2[],0,MATCH($A20,Table_query__2[#Headers],0))&""))} -> 92 | F20: ⚠️ | G20: ว่าง 62 แถว และ 13 เซลล์มีช่องว่างหัว/ท้ายหรือซ้อน → ต้อง TRIM ก่อน group
A21: Name_List | B21: =COUNTA(INDEX(Table_query__2[],0,MATCH($A21,Table_query__2[#Headers],0))) -> 971 | C21: =$B$5-B21 -> 2 | D21: =B21/$B$5 -> 0.9979445 | E21: {=SUMPRODUCT((INDEX(Table_query__2[],0,MATCH($A21,Table_query__2[#Headers],0))<>"")/COUNTIF(INDEX(Table_query__2[],0,MATCH($A21,Table_query__2[#Headers],0)),INDEX(Table_query__2[],0,MATCH($A21,Table_query__2[#Headers],0))&""))} -> 10 | F21: ❌ | G21: 828 จาก 973 แถว (85.1%) เป็น "Other (อื่นๆ)" → แทบไม่มีคุณค่าในการจำแนกหรือทำ filter
A22: Remark_List | B22: =COUNTA(INDEX(Table_query__2[],0,MATCH($A22,Table_query__2[#Headers],0))) -> 971 | C22: =$B$5-B22 -> 2 | D22: =B22/$B$5 -> 0.9979445 | E22: {=SUMPRODUCT((INDEX(Table_query__2[],0,MATCH($A22,Table_query__2[#Headers],0))<>"")/COUNTIF(INDEX(Table_query__2[],0,MATCH($A22,Table_query__2[#Headers],0)),INDEX(Table_query__2[],0,MATCH($A22,Table_query__2[#Headers],0))&""))} -> 528 | F22: ✅ | G22: คอลัมน์คำอธิบายหลักของเครื่องจักร เติม 99.8% แต่ 211 เซลล์มีช่องว่างเกิน; มี 8 แถวอ้างอิงรหัส QR อื่นในวงเล็บ
A23: Section | B23: =COUNTA(INDEX(Table_query__2[],0,MATCH($A23,Table_query__2[#Headers],0))) -> 939 | C23: =$B$5-B23 -> 34 | D23: =B23/$B$5 -> 0.96505653 | E23: {=SUMPRODUCT((INDEX(Table_query__2[],0,MATCH($A23,Table_query__2[#Headers],0))<>"")/COUNTIF(INDEX(Table_query__2[],0,MATCH($A23,Table_query__2[#Headers],0)),INDEX(Table_query__2[],0,MATCH($A23,Table_query__2[#Headers],0))&""))} -> 18 | F23: ⚠️ | G23: ว่าง 34 แถว ซึ่ง 29 แถวมี Department อยู่ → เติมอัตโนมัติจาก prefix ของ Department ได้; พบขัดกัน 1 แถว (แถว 862: HT vs YMQ)
A24: Name_Machine_Production | B24: =COUNTA(INDEX(Table_query__2[],0,MATCH($A24,Table_query__2[#Headers],0))) -> 719 | C24: =$B$5-B24 -> 254 | D24: =B24/$B$5 -> 0.7389517 | E24: {=SUMPRODUCT((INDEX(Table_query__2[],0,MATCH($A24,Table_query__2[#Headers],0))<>"")/COUNTIF(INDEX(Table_query__2[],0,MATCH($A24,Table_query__2[#Headers],0)),INDEX(Table_query__2[],0,MATCH($A24,Table_query__2[#Headers],0))&""))} -> 188 | F24: ⚠️ | G24: ว่าง 254 แถว (26.1%) → ใช้เป็นข้อมูลเสริมได้ แต่อย่าใช้เป็นมิติหลักของรายงาน
A25: Status | B25: =COUNTA(INDEX(Table_query__2[],0,MATCH($A25,Table_query__2[#Headers],0))) -> 92 | C25: =$B$5-B25 -> 881 | D25: =B25/$B$5 -> 0.094552929 | E25: {=SUMPRODUCT((INDEX(Table_query__2[],0,MATCH($A25,Table_query__2[#Headers],0))<>"")/COUNTIF(INDEX(Table_query__2[],0,MATCH($A25,Table_query__2[#Headers],0)),INDEX(Table_query__2[],0,MATCH($A25,Table_query__2[#Headers],0))&""))} -> 3 | F25: ❌ | G25: ว่าง 881 แถว (90.5%) มีค่าเพียง 92 แถว (Approve 46 / New 40 / Reject 6) → สรุปสถานะเครื่องทั้งโรงงานไม่ได้
A26: Item Type | B26: =COUNTA(INDEX(Table_query__2[],0,MATCH($A26,Table_query__2[#Headers],0))) -> 973 | C26: =$B$5-B26 -> 0 | D26: =B26/$B$5 -> 1 | E26: {=SUMPRODUCT((INDEX(Table_query__2[],0,MATCH($A26,Table_query__2[#Headers],0))<>"")/COUNTIF(INDEX(Table_query__2[],0,MATCH($A26,Table_query__2[#Headers],0)),INDEX(Table_query__2[],0,MATCH($A26,Table_query__2[#Headers],0))&""))} -> 1 | F26: ❌ | G26: ค่าเดียวทั้งคอลัมน์ ("Item") → ไม่มีข้อมูล ตัดออกจากชุดข้อมูลสะอาด
A27: Path | B27: =COUNTA(INDEX(Table_query__2[],0,MATCH($A27,Table_query__2[#Headers],0))) -> 973 | C27: =$B$5-B27 -> 0 | D27: =B27/$B$5 -> 1 | E27: {=SUMPRODUCT((INDEX(Table_query__2[],0,MATCH($A27,Table_query__2[#Headers],0))<>"")/COUNTIF(INDEX(Table_query__2[],0,MATCH($A27,Table_query__2[#Headers],0)),INDEX(Table_query__2[],0,MATCH($A27,Table_query__2[#Headers],0))&""))} -> 1 | F27: ❌ | G27: ค่าเดียวทั้งคอลัมน์ (SharePoint list path) → metadata ไม่ใช่ข้อมูลธุรกิจ ตัดออก
A29: 3. สิ่งที่ต้องแก้ / Issues & proposed fixes
A30: ระดับ | B30: ปัญหา | C30: จำนวน | D30: วิธีแก้ที่เสนอ
A31: สูง | B31: QR_Code_List ซ้ำ — เป็น primary key ไม่ได้ทันที | C31: 3 รหัส / 6 แถว | D31: สร้างคอลัมน์ Dup_Count + Row_Key (รหัส + ลำดับ) และติดธง DUPLICATE_QR — ไม่ลบแถวให้เอง
A32: สูง | B32: Status ว่างเกือบทั้งคอลัมน์ | C32: 881 / 973 (90.5%) | D32: เติม "NOT_SPECIFIED" และติดธง MISSING_STATUS — ห้ามเดาค่า
A33: สูง | B33: No เป็นตัวเลขที่เก็บเป็นข้อความ + ว่าง | C33: 887 text / 86 ว่าง | D33: แปลงเป็นตัวเลขจริงด้วย VALUE() และเลิกใช้เป็น key
A34: กลาง | B34: ช่องว่างเกิน/ท้ายช่องว่าง → group ผิด | C34: 211 (Remark) + 13 (Cost_Center) + 7 | D34: ใช้ TRIM(UPPER(...)) ทุกคอลัมน์ข้อความ
A35: กลาง | B35: ค่า placeholder "-" และ "." ใน Location/Department | C35: 8 เซลล์ | D35: แปลงเป็น "UNKNOWN" ตามรายการ Invalid_Placeholders ใน Cleaning_Rules
A36: กลาง | B36: Section ว่างแต่ Department มีค่า | C36: 29 แถว | D36: สร้าง Section_Derived จาก prefix ตัวอักษรของ Department และติดธง SECTION_DERIVED
A37: กลาง | B37: Department ตั้งชื่อไม่เป็นมาตรฐาน (สะกดผิด/ตัวคั่น) | C37: 53 ค่า | D37: แมพค่าที่รู้จักผิด (Assambly→Assembly) ผ่านตาราง Dept_Map ที่แก้เพิ่มเองได้
A38: ต่ำ | B38: Item Type / Path เป็นค่าเดียวทั้งคอลัมน์ | C38: 973 แถว | D38: ตัดออกจากชุดข้อมูลสะอาด
A39: ต่ำ | B39: วงเล็บใน Remark — ส่วนใหน่เป็น spec เครื่องจริง | C39: (SURFACE) 9, (OVER HAUL) 5, (AUTO) 3, (2 HEAD) 5, (OD1..3), (LINE 1/2) | D39: เก็บไว้ตามเดิม — ไม่ตัดวงเล็บทิ้งทั้งหมด; ดึงเฉพาะ (XX-000) 8 แถวออกเป็น Related_QR_Ref
A41: 4. สรุปความพร้อม / Verdict
A42: การใช้งาน | B42: สรุป | C42: เหตุผล
A43: ทะเบียนทรัพย์สิน / นับจำนวนเครื่อง | B43: ✅ พร้อมหลังทำความสะอาด | C43: QR/Location/Department/Section เติม >96% — นับเครื่องตามโรงงาน/แผนก/กลุ่มงานได้
A44: ค้นหาเครื่องจาก QR หรือชื่อ | B44: ✅ พร้อม | C44: Remark_List เติม 99.8% เป็นชื่อเครื่องที่ใช้ค้นหาได้จริง
...

Sheet Cleaning_Rules
A1: ตารางกฎการทำความสะอาด / Cleaning Rules
A2: ⚠️ หากต้องเพิ่มกฎ ให้แทรกแถว (Insert Row) กลางช่วงที่มีค่าอยู่เท่านั้น ห้ามเพิ่มต่อท้ายช่วง — แถวว่างในช่วง lookup จะทำให้ผลลัพธ์เพี้ยน
A4: กฎ 1 — ค่า placeholder ที่ถือเสมือนว่าง (Invalid_Placeholders) | E4: กฎ 6 — อ้างอิง prefix รหัส QR (ให้ผู้ใช้กรอกความหมาย)
A5: ค่าที่ไม่ใช้ข้อมูลจริง | E5: Prefix | F5: จำนวนแถว | G5: ความหมาย / ประเภทเครื่อง (กรอกเอง)
A6: . | E6: CH | F6: 243
A7: - | E7: GR | F7: 207
A8: N/A | E8: AS | F8: 162
A9: NA | E9: WA | F9: 75
A10: TBD | E10: DE | F10: 50
A11: NULL | E11: SU | F11: 34
E12: MA | F12: 33
A13: กฎ 2 — แมพค่า Location มาตรฐาน (Location_Map) | E13: PK | F13: 24
A14: ค่าเดิม (UPPER) | B14: ค่ามาตรฐาน | E14: FI | F14: 22
A15: FACTORY1 | B15: FACTORY1 | E15: AR | F15: 20
A16: FACTORY2 | B16: FACTORY2 | E16: ALL | F16: 13
A17: FACTORY3 | B17: FACTORY3 | E17: L | F17: 8
A18: ALL FACTORY | B18: ALL FACTORY | E18: M | F18: 7
A19: UTILITY | B19: UTILITY | E19: KT | F19: 6
A20: TOOLING | B20: TOOLING | E20: HT | F20: 6
E21: YMQ | F21: 5
A22: กฎ 3 — แก้ชื่อ Department ที่สะกดผิด/ไม่ตรงมาตรฐาน (Department_Map) | E22: BF | F22: 5
A23: ค่าเดิม (UPPER) | B23: ค่ามาตรฐาน | E23: WT | F23: 5
A24: NB ASSAMBLY1 | B24: NB ASSEMBLY1 | E24: IH | F24: 4
A25: WP ASSAMBLY1 | B25: WP ASSEMBLY1 | E25: LA | F25: 4
A26: WP ASSAMBLY2 | B26: WP ASSEMBLY2 | E26: BL | F26: 3
A27: TOOL SHOP | B27: TOOLING SHOP | E27: RL | F27: 3
A28: TOOLING ENGINEER | B28: TOOLING ENGINEER | E28: MI | F28: 3
E29: DR | F29: 3
A30: กฎ 4 — แมพค่า Status (Status_Map) | E30: CTG | F30: 3
A31: ค่าเดิม (UPPER) | B31: ค่ามาตรฐาน | E31: PA | F31: 2
A32: APPROVE | B32: APPROVED | E32: CU | F32: 2
A33: NEW | B33: NEW | E33: (ไม่มี prefix) | F33: 2
A34: REJECT | B34: REJECTED | E34: SP | F34: 2
E35: BG | F35: 2
A36: กฎ 5 — แมพค่า Name_List เป็นหมวดมาตรฐาน (Category_Map) | E36: CTO | F36: 2
A37: ค่าเดิม (UPPER) | B37: ค่ามาตรฐาน | C37: หมายเหตุ | E37: PR | F37: 1
A38: OTHER (อื่นๆ) | B38: OTHER | C38: 828 แถว — ไม่ช่วยจำแนก | E38: COM | F38: 1
A39: TOOL (เครื่องมือ) | B39: TOOL | E39: BP | F39: 1
A40: GRIDLING | B40: GRINDING | C40: สะกดผิดในข้อมูลต้นทาง | E40: ML | F40: 1
A41: CHECK | B41: CHECK | E41: CNCTU | F41: 1
...

Sheet query (2)
A1: No | B1: QR_Code_List | C1: Location_List | D1: Department_List | E1: RESPONSIBLE | F1: Cost_Center | G1: Name_List | H1: Remark_List | I1: Section | J1: Name_Machine_Production | K1: Status | L1: Item Type | M1: Path
A2: 1 | B2: AS-955 | C2: FACTORY3 | D2: KWD5 | E2: Assembly | F2: 1016-KW5AI | G2: Assembly | H2: Auto bush press machine | I2: KWD | J2: Auto bush press | L2: Item | M2: sites/ao-nbmt-portal_classic/en-mt/Lists/PM_Machine_List
A3: 2 | B3: AS-962 | C3: FACTORY3 | D3: KWD7 | E3: Assembly | F3: 1025-KW7AI | G3: Assembly | H3: Auto bush press machine | I3: KWD | J3: Auto bush press | L3: Item | M3: sites/ao-nbmt-portal_classic/en-mt/Lists/PM_Machine_List
A4: 3 | B4: AS-909 | C4: FACTORY3 | D4: KWD4 | E4: Assembly | F4: 1013-KW4AI | G4: Assembly | H4: Automatic assembly machine | I4: KWD | J4: Automatic assembly | L4: Item | M4: sites/ao-nbmt-portal_classic/en-mt/Lists/PM_Machine_List
A5: 4 | B5: AS-956 | C5: FACTORY3 | D5: KWD1 | E5: Assembly | F5: 1004-KW1AI | G5: Assembly | H5: Automatic assembly machine | I5: KWD | J5: Automatic assembly | L5: Item | M5: sites/ao-nbmt-portal_classic/en-mt/Lists/PM_Machine_List
A6: 5 | B6: AS-924 | C6: FACTORY3 | D6: KWD5 | E6: Assembly | F6: 1016-KW5AI | G6: Assembly | H6: Automatic assembly machine | I6: KWD | J6: Automatic assembly | L6: Item | M6: sites/ao-nbmt-portal_classic/en-mt/Lists/PM_Machine_List
A7: 6 | B7: AS-700 | C7: FACTORY3 | D7: KWD6 | E7: Assembly | F7: 1019-KW6AI | G7: Assembly | H7: Automatic assembly machine | I7: KWD | J7: Automatic assembly | L7: Item | M7: sites/ao-nbmt-portal_classic/en-mt/Lists/PM_Machine_List
A8: 7 | B8: AS-833 | C8: FACTORY3 | D8: KWD7 | E8: Assembly | F8: 1025-KW7AI | G8: Assembly | H8: Automatic assembly machine | I8: KWD | J8: Automatic assembly | L8: Item | M8: sites/ao-nbmt-portal_classic/en-mt/Lists/PM_Machine_List
A9: 8 | B9: AS-950 | C9: FACTORY3 | D9: KWD3 | E9: Assembly | F9: 1010-KW3AI | G9: Assembly | H9: Automatic assembly machine | I9: KWD | J9: Automatic assembly | L9: Item | M9: sites/ao-nbmt-portal_classic/en-mt/Lists/PM_Machine_List
A10: 9 | B10: AS-949 | C10: FACTORY3 | D10: KWD2 | E10: Assembly | F10: 1007-KW2AI | G10: Assembly | H10: Automatic assembly machine | I10: KWD | J10: Automatic assembly | L10: Item | M10: sites/ao-nbmt-portal_classic/en-mt/Lists/PM_Machine_List
A11: 10 | B11: CH-014 | C11: FACTORY3 | D11: KWD1 | E11: Assembly | F11: 1004-KW1AI | G11: Check | H11: Automation vibration testing machine | I11: KWD | J11: Noise inspection auto | L11: Item | M11: sites/ao-nbmt-portal_classic/en-mt/Lists/PM_Machine_List
A12: 11 | B12: CH-263 | C12: FACTORY3 | D12: KWD2 | E12: Assembly | F12: 1007-KW2AI | G12: Check | H12: Automation vibration testing machine | I12: KWD | J12: Noise inspection auto | L12: Item | M12: sites/ao-nbmt-portal_classic/en-mt/Lists/PM_Machine_List
A13: 12 | B13: CH-349 | C13: FACTORY3 | D13: KWD3 | E13: Assembly | F13: 1010-KW3AI | G13: Check | H13: Automation vibration testing machine | I13: KWD | J13: Noise inspection auto | L13: Item | M13: sites/ao-nbmt-portal_classic/en-mt/Lists/PM_Machine_List
... A180: 179 | B180: CH-850 | C180: FACTORY3 | D180: KWD7 | E180: Assembly | F180: 1025-KW7AI | G180: Other (อื่นๆ) | H180: Weight checker | I180: KWD | J180: Weight checker | L180: Item | M180: sites/ao-nbmt-portal_classic/en-mt/Lists/PM_Machine_List
A181: 185 | B181: AR-247 | C181: FACTORY1 | G181: Other (อื่นๆ) | H181: Rust Prevention M/C | L181: Item | M181: sites/ao-nbmt-portal_classic/en-mt/Lists/PM_Machine_List
A182: 200 | B182: YMQ1 | C182: FACTORY1 | D182: HT | E182: Grinding 1 | F182: 2003-HT1 | G182: Other (อื่นๆ) | H182: Furnace1 | I182: HT | K182: Approve | L182: Item | M182: sites/ao-nbmt-portal_classic/en-mt/Lists/PM_Machine_List
A183: 201 | B183: YMQ2 | C183: FACTORY1 | D183: HT | E183: Grinding 1 | F183: 2004-HT2 | G183: Other (อื่นๆ) | H183: Furnace2 | I183: HT | K183: Approve | L183: Item | M183: sites/ao-nbmt-portal_classic/en-mt/Lists/PM_Machine_List
A184: 202 | B184: YMQ3 | C184: FACTORY1 | D184: HT | E184: Grinding 1 | F184: 2005-HT3 | G184: Other (อื่นๆ) | H184: Furnace3 | I184: HT | K184: Approve | L184: Item | M184: sites/ao-nbmt-portal_classic/en-mt/Lists/PM_Machine_List
A185: 203 | B185: YMQ4 | C185: FACTORY1 | D185: HT | E185: Grinding 1 | F185: 2006-HT4 | G185: Other (อื่นๆ) | H185: Furnace4 | I185: HT | K185: Approve | L185: Item | M185: sites/ao-nbmt-portal_classic/en-mt/Lists/PM_Machine_List
A186: 204 | B186: YMQ5 | C186: FACTORY1 | D186: HT | E186: Grinding 1 | F186: 2007-HT5 | G186: Other (อื่นๆ) | H186: Furnace5 | I186: HT | K186: Approve | L186: Item | M186: sites/ao-nbmt-portal_classic/en-mt/Lists/PM_Machine_List
A187: 205 | B187: GR-120 | C187: FACTORY2 | D187: MCB1 | E187: Grinding 2 | F187: 1303-MC1G | G187: Other (อื่นๆ) | H187: Inner ring raceway grinding M/C | I187: MCB | J187: B - Raceway grinding | L187: Item | M187: sites/ao-nbmt-portal_classic/en-mt/Lists/PM_Machine_List
A188: 206 | B188: GR-122 | C188: FACTORY2 | D188: MCB1 | E188: Grinding 2 | F188: 1303-MC1G | G188: Other (อื่นๆ) | H188: Inner ring bore grinding M/C | I188: MCB | J188: B - Bore grinding | L188: Item | M188: sites/ao-nbmt-portal_classic/en-mt/Lists/PM_Machine_List
A189: 207 | B189: DE-124 | C189: FACTORY2 | D189: MCB1 | E189: Grinding 2 | F189: 1303-MC1G | G189: Other (อื่นๆ) | H189: Demagnetizing for inner ring M/C | I189: MCB | J189: B - Demagnetizing | L189: Item | M189: sites/ao-nbmt-portal_classic/en-mt/Lists/PM_Machine_List
A190: 208 | B190: GR-125 | C190: FACTORY2 | D190: MCB1 | E190: Grinding 2 | F190: 1303-MC1G | G190: Other (อื่นๆ) | H190: Inner ring raceway super finish M/C | I190: MCB | J190: B - Raceway super finish | L190: Item | M190: sites/ao-nbmt-portal_classic/en-mt/Lists/PM_Machine_List
A191: 209 | B191: WA-913 | C191: FACTORY2 | D191: MCB1 | E191: Grinding 2 | F191: 1303-MC1G | G191: Other (อื่นๆ) | H191: Outer/Inner ring part wash equipment M/C (WA-132) | I191: MCB | J191: A&B - Part wash equipment | L191: Item | M191: sites/ao-nbmt-portal_classic/en-mt/Lists/PM_Machine_List
A192: 210 | B192: CH-914 | C192: FACTORY2 | D192: MCB1 | E192: Grinding 2 | F192: 1303-MC1G | G192: Other (อื่นๆ) | H192: Outer/Inner Eddy current tester M/C | I192: MCB | J192: A&B - E.C.T. | L192: Item | M192: sites/ao-nbmt-portal_classic/en-mt/Lists/PM_Machine_List
A193: 211 | B193: GR-129 | C193: FACTORY2 | D193: MCB1 | E193: Grinding 2 | F193: 1303-MC1G | G193: Other (อื่นๆ) | H193: Outer ring raceway grinding M/C | I193: MCB | J193: A - Raceway grinding | L193: Item | M193: sites/ao-nbmt-portal_classic/en-mt/Lists/PM_Machine_List
A194: 212 | B194: DE-130 | C194: FACTORY2 | D194: MCB1 | E194: Grinding 2 | F194: 1303-MC1G | G194: Other (อื่นๆ) | H194: Demagnetizing for outer ring M/C | I194: MCB | J194: A - Demagnetizing | L194: Item | M194: sites/ao-nbmt-portal_classic/en-mt/Lists/PM_Machine_List
A195: 213 | B195: GR-131 | C195: FACTORY2 | D195: MCB1 | E195: Grinding 2 | F195: 1303-MC1G | G195: Other (อื่นๆ) | H195: Outer ring raceway super finish M/C | I195: MCB | J195: A - Raceway super finish | L195: Item | M195: sites/ao-nbmt-portal_classic/en-mt/Lists/PM_Machine_List
