Workbook

Sheet Clean_PM_Plan
A1: ID | B1: Ref_ID_Work01 | C1: QRCODE_Clean | D1: Machine_Base_Name | E1: Machine_Code_In_Name | F1: LineLocation_Clean | G1: PositionName_Raw | H1: PositionName_Clean | I1: PM_Type | J1: PM_Type_Code | K1: StatusItems_Raw | L1: Status_EN | M1: TypeWork | N1: Action | O1: Priority | P1: Items_Raw | Q1: Items_Clean | R1: PartName_Clean | S1: Model_Clean | T1: Spare_ID | U1: Qty_Raw | V1: Qty_Clean | W1: Cost | X1: PeriodDay | Y1: PlanMonth | Z1: ActualMonth | AA1: LastPMDate | AB1: NextPMDate | AC1: Remark1_Clean | AD1: Remark2_Clean | AE1: Responsible_Email | AF1: Planner | AG1: Responsible | AH1: CdB_Before_Value | AI1: CdB_Before_Unit | AJ1: CdB_After_Value | AK1: CdB_After_Unit | AL1: Plan_Year | AM1: Plan_Year_Month | AN1: Is_Overdue | AO1: Search_Text | AP1: Data_Quality_Flag | AQ1: Has_Cost
A2: =IF('query (10)'!A2="","",'query (10)'!A2) -> 2 | B2: =IF('query (10)'!B2="","",'query (10)'!B2) | C2: =TRIM(UPPER('query (10)'!M2)) -> GR-721 | D2: =TRIM(UPPER(IFERROR(_xlfn.TEXTBEFORE('query (10)'!L2,"("),'query (10)'!L2))) -> OUTER RING RACEWAY GRINDING MACHINE. | E2: =IFERROR(TRIM(UPPER(_xlfn.TEXTBEFORE(_xlfn.TEXTAFTER('query (10)'!L2,"("),")"))),"") | F2: =TRIM('query (10)'!K2) -> MCB3 | G2: =IF('query (10)'!J2="","",'query (10)'!J2) -> Work Head | H2: =TRIM(UPPER('query (10)'!J2)) -> WORK HEAD | I2: =IF('query (10)'!F2="","",'query (10)'!F2) -> Condition-based Maintenance | J2: =IF('query (10)'!F2="","",IFERROR(INDEX(Cleaning_Rules!$B$14:$B$17,MATCH(TRIM('query (10)'!F2),Cleaning_Rules!$A$14:$A$17,0)),"UNKNOWN")) -> CBM | K2: =IF('query (10)'!G2="","",'query (10)'!G2) -> แก้ไขแผน | L2: =IF('query (10)'!G2="","MISSING",IFERROR(INDEX(Cleaning_Rules!$B$5:$B$10,MATCH(TRIM('query (10)'!G2),Cleaning_Rules!$A$5:$A$10,0)),"UNKNOWN")) -> PLAN_REVISED | M2: =IF('query (10)'!I2="","",'query (10)'!I2) -> Mechanical | N2: =IF('query (10)'!O2="","",'query (10)'!O2) -> Measure | O2: =IF('query (10)'!P2="","",'query (10)'!P2) -> Urgent | P2: =IF('query (10)'!N2="","",'query (10)'!N2) -> High Velocity Vibration of Work head unit 5.00 mm/s | Q2: =TRIM('query (10)'!N2) -> High Velocity Vibration of Work head unit 5.00 mm/s | R2: =TRIM(UPPER('query (10)'!R2)) | S2: =TRIM(UPPER('query (10)'!S2)) | T2: =IF('query (10)'!Q2="","",TRIM(UPPER('query (10)'!Q2))) | U2: =IF('query (10)'!T2="","",'query (10)'!T2) | V2: =IF('query (10)'!T2="","",IFERROR(VALUE('query (10)'!T2),"")) | W2: =IF('query (10)'!U2="","",'query (10)'!U2) -> 0 | X2: =IF('query (10)'!V2="","",'query (10)'!V2) | Y2: =IF('query (10)'!W2="","",'query (10)'!W2) -> 45902 | Z2: =IF('query (10)'!X2="","",'query (10)'!X2) -> 45902 | AA2: =IF('query (10)'!Y2="","",'query (10)'!Y2) | AB2: =IF('query (10)'!Z2="","",'query (10)'!Z2) | AC2: =IF(OR('query (10)'!AA2="",COUNTIF(Cleaning_Rules!$A$21:$A$26,TRIM('query (10)'!AA2))>0),"",TRIM('query (10)'!AA2)) | AD2: =IF('query (10)'!AB2="","",TRIM(IFERROR(_xlfn.TEXTBEFORE('query (10)'!AB2,"("),'query (10)'!AB2))) | AE2: =IFERROR(LOWER(TRIM(_xlfn.TEXTBEFORE(_xlfn.TEXTAFTER('query (10)'!AB2,"("),")"))),"") | AF2: =IF('query (10)'!AD2="","",TRIM('query (10)'!AD2)) -> เจษฎา ผิวบาง | AG2: =IF('query (10)'!AE2="","",TRIM('query (10)'!AE2)) | AH2: =IF('query (10)'!AF2="","",IFERROR(VALUE('query (10)'!AF2),"")) | AI2: =IF('query (10)'!AG2="","",TRIM('query (10)'!AG2)) | AJ2: =IF('query (10)'!AH2="","",IFERROR(VALUE('query (10)'!AH2),"")) | AK2: =IF('query (10)'!AI2="","",TRIM('query (10)'!AI2)) | AL2: =IF($Y2="","",YEAR($Y2)) -> 2025 | AM2: =IF($Y2="","",TEXT($Y2,"yyyy-mm")) -> 2025-09 | AN2: =IF(OR($AB2="",$L2="COMPLETED"),"",IF($AB2<TODAY(),"OVERDUE","ON_SCHEDULE")) | AO2: =_xlfn.TEXTJOIN(" | ",TRUE,$C2,$D2,$E2,$F2,$H2,$I2,$M2,$N2,$O2,$Q2,$R2,$S2,$T2,$AC2,$AD2,$AG2) -> GR-721 | OUTER RING RACEWAY GRINDING MACHINE. | MCB3 | WORK HEAD | Condition-based Maintenance | Mechanical | Measure | Urgent | High Velocity Vibration of Work head unit 5.00 mm/s | AP2: =_xlfn.TEXTJOIN("; ",TRUE,IF(COUNTA('query (10)'!A2:AK2)<=6,"NEAR_EMPTY_ROW",""),IF($K2="","MISSING_STATUS",""),IF(AND($K2="เสร็จสิ้น",$Z2=""),"DONE_NO_ACTUAL_DATE",""),IF(AND($I2="Condition-based Maintenance",$AH2=""),"CBM_NO_MEASUREMENT",""),IF(OR($X2="",$X2=0),"INVALID_PERIOD",""),IF(AND($AA2<>"",$AB2<>"",$AB2<$AA2),"DATE_SEQUENCE_ERROR",""),IF(AND($AB2<>"",$AB2>DATE(2030,12,31)),"DATE_OUTLIER",""),IF($C2="","MISSING_QRCODE",""),IF($J2="UNKNOWN","UNKNOWN_PM_TYPE",""),IF($L2="UNKNOWN","UNKNOWN_STATUS","")) -> CBM_NO_MEASUREMENT; INVALID_PERIOD | AQ2: =IF($W2="","",IF($W2>0,"YES","NO")) -> NO
A3: =IF('query (10)'!A3="","",'query (10)'!A3) -> 3 | B3: =IF('query (10)'!B3="","",'query (10)'!B3) | C3: =TRIM(UPPER('query (10)'!M3)) -> GR-721 | D3: =TRIM(UPPER(IFERROR(_xlfn.TEXTBEFORE('query (10)'!L3,"("),'query (10)'!L3))) -> OUTER RING RACEWAY GRINDING MACHINE. | E3: =IFERROR(TRIM(UPPER(_xlfn.TEXTBEFORE(_xlfn.TEXTAFTER('query (10)'!L3,"("),")"))),"") | F3: =TRIM('query (10)'!K3) -> MCB3 | G3: =IF('query (10)'!J3="","",'query (10)'!J3) -> Work Head | H3: =TRIM(UPPER('query (10)'!J3)) -> WORK HEAD | I3: =IF('query (10)'!F3="","",'query (10)'!F3) -> Usage-based Maintenance | J3: =IF('query (10)'!F3="","",IFERROR(INDEX(Cleaning_Rules!$B$14:$B$17,MATCH(TRIM('query (10)'!F3),Cleaning_Rules!$A$14:$A$17,0)),"UNKNOWN")) -> UBM | K3: =IF('query (10)'!G3="","",'query (10)'!G3) -> เลื่อนแผน | L3: =IF('query (10)'!G3="","MISSING",IFERROR(INDEX(Cleaning_Rules!$B$5:$B$10,MATCH(TRIM('query (10)'!G3),Cleaning_Rules!$A$5:$A$10,0)),"UNKNOWN")) -> POSTPONED | M3: =IF('query (10)'!I3="","",'query (10)'!I3) -> Mechanical | N3: =IF('query (10)'!O3="","",'query (10)'!O3) -> Part Change | O3: =IF('query (10)'!P3="","",'query (10)'!P3) -> Urgent | P3: =IF('query (10)'!N3="","",'query (10)'!N3) -> Change belt of 5000 hr | Q3: =TRIM('query (10)'!N3) -> Change belt of 5000 hr | R3: =TRIM(UPPER('query (10)'!R3)) -> BELT | S3: =TRIM(UPPER('query (10)'!S3)) -> 5M580 | T3: =IF('query (10)'!Q3="","",TRIM(UPPER('query (10)'!Q3))) | U3: =IF('query (10)'!T3="","",'query (10)'!T3) -> 1 | V3: =IF('query (10)'!T3="","",IFERROR(VALUE('query (10)'!T3),"")) -> 1 | W3: =IF('query (10)'!U3="","",'query (10)'!U3) -> 570 | X3: =IF('query (10)'!V3="","",'query (10)'!V3) | Y3: =IF('query (10)'!W3="","",'query (10)'!W3) -> 45902 | Z3: =IF('query (10)'!X3="","",'query (10)'!X3) -> 45902 | AA3: =IF('query (10)'!Y3="","",'query (10)'!Y3) | AB3: =IF('query (10)'!Z3="","",'query (10)'!Z3) -> 45932 | AC3: =IF(OR('query (10)'!AA3="",COUNTIF(Cleaning_Rules!$A$21:$A$26,TRIM('query (10)'!AA3))>0),"",TRIM('query (10)'!AA3)) -> รออะไหล่ | AD3: =IF('query (10)'!AB3="","",TRIM(IFERROR(_xlfn.TEXTBEFORE('query (10)'!AB3,"("),'query (10)'!AB3))) | AE3: =IFERROR(LOWER(TRIM(_xlfn.TEXTBEFORE(_xlfn.TEXTAFTER('query (10)'!AB3,"("),")"))),"") | AF3: =IF('query (10)'!AD3="","",TRIM('query (10)'!AD3)) -> เจษฎา ผิวบาง | AG3: =IF('query (10)'!AE3="","",TRIM('query (10)'!AE3)) | AH3: =IF('query (10)'!AF3="","",IFERROR(VALUE('query (10)'!AF3),"")) | AI3: =IF('query (10)'!AG3="","",TRIM('query (10)'!AG3)) | AJ3: =IF('query (10)'!AH3="","",IFERROR(VALUE('query (10)'!AH3),"")) | AK3: =IF('query (10)'!AI3="","",TRIM('query (10)'!AI3)) | AL3: =IF($Y3="","",YEAR($Y3)) -> 2025 | AM3: =IF($Y3="","",TEXT($Y3,"yyyy-mm")) -> 2025-09 | AN3: =IF(OR($AB3="",$L3="COMPLETED"),"",IF($AB3<TODAY(),"OVERDUE","ON_SCHEDULE")) -> OVERDUE | AO3: =_xlfn.TEXTJOIN(" | ",TRUE,$C3,$D3,$E3,$F3,$H3,$I3,$M3,$N3,$O3,$Q3,$R3,$S3,$T3,$AC3,$AD3,$AG3) -> GR-721 | OUTER RING RACEWAY GRINDING MACHINE. | MCB3 | WORK HEAD | Usage-based Maintenance | Mechanical | Part Change | Urgent | Change belt of 5000 hr | BELT | 5M580 | รออะไหล่ | AP3: =_xlfn.TEXTJOIN("; ",TRUE,IF(COUNTA('query (10)'!A3:AK3)<=6,"NEAR_EMPTY_ROW",""),IF($K3="","MISSING_STATUS",""),IF(AND($K3="เสร็จสิ้น",$Z3=""),"DONE_NO_ACTUAL_DATE",""),IF(AND($I3="Condition-based Maintenance",$AH3=""),"CBM_NO_MEASUREMENT",""),IF(OR($X3="",$X3=0),"INVALID_PERIOD",""),IF(AND($AA3<>"",$AB3<>"",$AB3<$AA3),"DATE_SEQUENCE_ERROR",""),IF(AND($AB3<>"",$AB3>DATE(2030,12,31)),"DATE_OUTLIER",""),IF($C3="","MISSING_QRCODE",""),IF($J3="UNKNOWN","UNKNOWN_PM_TYPE",""),IF($L3="UNKNOWN","UNKNOWN_STATUS","")) -> INVALID_PERIOD | AQ3: =IF($W3="","",IF($W3>0,"YES","NO")) -> YES
A4: =IF('query (10)'!A4="","",'query (10)'!A4) -> 6 | B4: =IF('query (10)'!B4="","",'query (10)'!B4) | C4: =TRIM(UPPER('query (10)'!M4)) -> GR-721 | D4: =TRIM(UPPER(IFERROR(_xlfn.TEXTBEFORE('query (10)'!L4,"("),'query (10)'!L4))) -> OUTER RING RACEWAY GRINDING MACHINE. | E4: =IFERROR(TRIM(UPPER(_xlfn.TEXTBEFORE(_xlfn.TEXTAFTER('query (10)'!L4,"("),")"))),"") | F4: =TRIM('query (10)'!K4) -> MCB3 | G4: =IF('query (10)'!J4="","",'query (10)'!J4) -> Work Head | H4: =TRIM(UPPER('query (10)'!J4)) -> WORK HEAD | I4: =IF('query (10)'!F4="","",'query (10)'!F4) -> Predictive Maintenance | J4: =IF('query (10)'!F4="","",IFERROR(INDEX(Cleaning_Rules!$B$14:$B$17,MATCH(TRIM('query (10)'!F4),Cleaning_Rules!$A$14:$A$17,0)),"UNKNOWN")) -> PdM | K4: =IF('query (10)'!G4="","",'query (10)'!G4) -> แก้ไขแผน | L4: =IF('query (10)'!G4="","MISSING",IFERROR(INDEX(Cleaning_Rules!$B$5:$B$10,MATCH(TRIM('query (10)'!G4),Cleaning_Rules!$A$5:$A$10,0)),"UNKNOWN")) -> PLAN_REVISED | M4: =IF('query (10)'!I4="","",'query (10)'!I4) -> Mechanical | N4: =IF('query (10)'!O4="","",'query (10)'!O4) -> Inspection | O4: =IF('query (10)'!P4="","",'query (10)'!P4) -> Urgent | P4: =IF('query (10)'!N4="","",'query (10)'!N4) -> AI Alert!! Extra work high temperature of work head motor | Q4: =TRIM('query (10)'!N4) -> AI Alert!! Extra work high temperature of work head motor | R4: =TRIM(UPPER('query (10)'!R4)) | S4: =TRIM(UPPER('query (10)'!S4)) | T4: =IF('query (10)'!Q4="","",TRIM(UPPER('query (10)'!Q4))) | U4: =IF('query (10)'!T4="","",'query (10)'!T4) | V4: =IF('query (10)'!T4="","",IFERROR(VALUE('query (10)'!T4),"")) | W4: =IF('query (10)'!U4="","",'query (10)'!U4) -> 0 | X4: =IF('query (10)'!V4="","",'query (10)'!V4) | Y4: =IF('query (10)'!W4="","",'query (10)'!W4) -> 45902 | Z4: =IF('query (10)'!X4="","",'query (10)'!X4) -> 45902 | AA4: =IF('query (10)'!Y4="","",'query (10)'!Y4) | AB4: =IF('query (10)'!Z4="","",'query (10)'!Z4) | AC4: =IF(OR('query (10)'!AA4="",COUNTIF(Cleaning_Rules!$A$21:$A$26,TRIM('query (10)'!AA4))>0),"",TRIM('query (10)'!AA4)) | AD4: =IF('query (10)'!AB4="","",TRIM(IFERROR(_xlfn.TEXTBEFORE('query (10)'!AB4,"("),'query (10)'!AB4))) | AE4: =IFERROR(LOWER(TRIM(_xlfn.TEXTBEFORE(_xlfn.TEXTAFTER('query (10)'!AB4,"("),")"))),"") | AF4: =IF('query (10)'!AD4="","",TRIM('query (10)'!AD4)) -> Automate | AG4: =IF('query (10)'!AE4="","",TRIM('query (10)'!AE4)) | AH4: =IF('query (10)'!AF4="","",IFERROR(VALUE('query (10)'!AF4),"")) | AI4: =IF('query (10)'!AG4="","",TRIM('query (10)'!AG4)) | AJ4: =IF('query (10)'!AH4="","",IFERROR(VALUE('query (10)'!AH4),"")) | AK4: =IF('query (10)'!AI4="","",TRIM('query (10)'!AI4)) | AL4: =IF($Y4="","",YEAR($Y4)) -> 2025 | AM4: =IF($Y4="","",TEXT($Y4,"yyyy-mm")) -> 2025-09 | AN4: =IF(OR($AB4="",$L4="COMPLETED"),"",IF($AB4<TODAY(),"OVERDUE","ON_SCHEDULE")) | AO4: =_xlfn.TEXTJOIN(" | ",TRUE,$C4,$D4,$E4,$F4,$H4,$I4,$M4,$N4,$O4,$Q4,$R4,$S4,$T4,$AC4,$AD4,$AG4) -> GR-721 | OUTER RING RACEWAY GRINDING MACHINE. | MCB3 | WORK HEAD | Predictive Maintenance | Mechanical | Inspection | Urgent | AI Alert!! Extra work high temperature of work head motor | AP4: =_xlfn.TEXTJOIN("; ",TRUE,IF(COUNTA('query (10)'!A4:AK4)<=6,"NEAR_EMPTY_ROW",""),IF($K4="","MISSING_STATUS",""),IF(AND($K4="เสร็จสิ้น",$Z4=""),"DONE_NO_ACTUAL_DATE",""),IF(AND($I4="Condition-based Maintenance",$AH4=""),"CBM_NO_MEASUREMENT",""),IF(OR($X4="",$X4=0),"INVALID_PERIOD",""),IF(AND($AA4<>"",$AB4<>"",$AB4<$AA4),"DATE_SEQUENCE_ERROR",""),IF(AND($AB4<>"",$AB4>DATE(2030,12,31)),"DATE_OUTLIER",""),IF($C4="","MISSING_QRCODE",""),IF($J4="UNKNOWN","UNKNOWN_PM_TYPE",""),IF($L4="UNKNOWN","UNKNOWN_STATUS","")) -> INVALID_PERIOD | AQ4: =IF($W4="","",IF($W4>0,"YES","NO")) -> NO
A5: =IF('query (10)'!A5="","",'query (10)'!A5) -> 7 | B5: =IF('query (10)'!B5="","",'query (10)'!B5) | C5: =TRIM(UPPER('query (10)'!M5)) -> GR-721 | D5: =TRIM(UPPER(IFERROR(_xlfn.TEXTBEFORE('query (10)'!L5,"("),'query (10)'!L5))) -> OUTER RING RACEWAY GRINDING MACHINE. | E5: =IFERROR(TRIM(UPPER(_xlfn.TEXTBEFORE(_xlfn.TEXTAFTER('query (10)'!L5,"("),")"))),"") | F5: =TRIM('query (10)'!K5) -> MCB3 | G5: =IF('query (10)'!J5="","",'query (10)'!J5) -> Work Head | H5: =TRIM(UPPER('query (10)'!J5)) -> WORK HEAD | I5: =IF('query (10)'!F5="","",'query (10)'!F5) -> Predictive Maintenance | J5: =IF('query (10)'!F5="","",IFERROR(INDEX(Cleaning_Rules!$B$14:$B$17,MATCH(TRIM('query (10)'!F5),Cleaning_Rules!$A$14:$A$17,0)),"UNKNOWN")) -> PdM | K5: =IF('query (10)'!G5="","",'query (10)'!G5) -> แก้ไขแผน | L5: =IF('query (10)'!G5="","MISSING",IFERROR(INDEX(Cleaning_Rules!$B$5:$B$10,MATCH(TRIM('query (10)'!G5),Cleaning_Rules!$A$5:$A$10,0)),"UNKNOWN")) -> PLAN_REVISED | M5: =IF('query (10)'!I5="","",'query (10)'!I5) -> Mechanical | N5: =IF('query (10)'!O5="","",'query (10)'!O5) -> Adjust | O5: =IF('query (10)'!P5="","",'query (10)'!P5) -> Medium | P5: =IF('query (10)'!N5="","",'query (10)'!N5) -> Reduce motor speed by 10% to extend service life. | Q5: =TRIM('query (10)'!N5) -> Reduce motor speed by 10% to extend service life. | R5: =TRIM(UPPER('query (10)'!R5)) | S5: =TRIM(UPPER('query (10)'!S5)) | T5: =IF('query (10)'!Q5="","",TRIM(UPPER('query (10)'!Q5))) | U5: =IF('query (10)'!T5="","",'query (10)'!T5) | V5: =IF('query (10)'!T5="","",IFERROR(VALUE('query (10)'!T5),"")) | W5: =IF('query (10)'!U5="","",'query (10)'!U5) -> 0 | X5: =IF('query (10)'!V5="","",'query (10)'!V5) | Y5: =IF('query (10)'!W5="","",'query (10)'!W5) -> 45902 | Z5: =IF('query (10)'!X5="","",'query (10)'!X5) -> 45902 | AA5: =IF('query (10)'!Y5="","",'query (10)'!Y5) | AB5: =IF('query (10)'!Z5="","",'query (10)'!Z5) | AC5: =IF(OR('query (10)'!AA5="",COUNTIF(Cleaning_Rules!$A$21:$A$26,TRIM('query (10)'!AA5))>0),"",TRIM('query (10)'!AA5)) | AD5: =IF('query (10)'!AB5="","",TRIM(IFERROR(_xlfn.TEXTBEFORE('query (10)'!AB5,"("),'query (10)'!AB5))) | AE5: =IFERROR(LOWER(TRIM(_xlfn.TEXTBEFORE(_xlfn.TEXTAFTER('query (10)'!AB5,"("),")"))),"") | AF5: =IF('query (10)'!AD5="","",TRIM('query (10)'!AD5)) -> เจษฎา ผิวบาง | AG5: =IF('query (10)'!AE5="","",TRIM('query (10)'!AE5)) | AH5: =IF('query (10)'!AF5="","",IFERROR(VALUE('query (10)'!AF5),"")) | AI5: =IF('query (10)'!AG5="","",TRIM('query (10)'!AG5)) | AJ5: =IF('query (10)'!AH5="","",IFERROR(VALUE('query (10)'!AH5),"")) | AK5: =IF('query (10)'!AI5="","",TRIM('query (10)'!AI5)) | AL5: =IF($Y5="","",YEAR($Y5)) -> 2025 | AM5: =IF($Y5="","",TEXT($Y5,"yyyy-mm")) -> 2025-09 | AN5: =IF(OR($AB5="",$L5="COMPLETED"),"",IF($AB5<TODAY(),"OVERDUE","ON_SCHEDULE")) | AO5: =_xlfn.TEXTJOIN(" | ",TRUE,$C5,$D5,$E5,$F5,$H5,$I5,$M5,$N5,$O5,$Q5,$R5,$S5,$T5,$AC5,$AD5,$AG5) -> GR-721 | OUTER RING RACEWAY GRINDING MACHINE. | MCB3 | WORK HEAD | Predictive Maintenance | Mechanical | Adjust | Medium | Reduce motor speed by 10% to extend service life. | AP5: =_xlfn.TEXTJOIN("; ",TRUE,IF(COUNTA('query (10)'!A5:AK5)<=6,"NEAR_EMPTY_ROW",""),IF($K5="","MISSING_STATUS",""),IF(AND($K5="เสร็จสิ้น",$Z5=""),"DONE_NO_ACTUAL_DATE",""),IF(AND($I5="Condition-based Maintenance",$AH5=""),"CBM_NO_MEASUREMENT",""),IF(OR($X5="",$X5=0),"INVALID_PERIOD",""),IF(AND($AA5<>"",$AB5<>"",$AB5<$AA5),"DATE_SEQUENCE_ERROR",""),IF(AND($AB5<>"",$AB5>DATE(2030,12,31)),"DATE_OUTLIER",""),IF($C5="","MISSING_QRCODE",""),IF($J5="UNKNOWN","UNKNOWN_PM_TYPE",""),IF($L5="UNKNOWN","UNKNOWN_STATUS","")) -> INVALID_PERIOD | AQ5: =IF($W5="","",IF($W5>0,"YES","NO")) -> NO
A6: =IF('query (10)'!A6="","",'query (10)'!A6) -> 15 | B6: =IF('query (10)'!B6="","",'query (10)'!B6) -> 17222 | C6: =TRIM(UPPER('query (10)'!M6)) -> GR-150 | D6: =TRIM(UPPER(IFERROR(_xlfn.TEXTBEFORE('query (10)'!L6,"("),'query (10)'!L6))) -> OUTER RING RACEWAY SUPER FINISH M/C | E6: =IFERROR(TRIM(UPPER(_xlfn.TEXTBEFORE(_xlfn.TEXTAFTER('query (10)'!L6,"("),")"))),"") | F6: =TRIM('query (10)'!K6) -> BWD2 | G6: =IF('query (10)'!J6="","",'query (10)'!J6) -> Dresser | H6: =TRIM(UPPER('query (10)'!J6)) -> DRESSER | I6: =IF('query (10)'!F6="","",'query (10)'!F6) -> Time-based Maintenance | J6: =IF('query (10)'!F6="","",IFERROR(INDEX(Cleaning_Rules!$B$14:$B$17,MATCH(TRIM('query (10)'!F6),Cleaning_Rules!$A$14:$A$17,0)),"UNKNOWN")) -> TBM | K6: =IF('query (10)'!G6="","",'query (10)'!G6) -> เสร็จสิ้น | L6: =IF('query (10)'!G6="","MISSING",IFERROR(INDEX(Cleaning_Rules!$B$5:$B$10,MATCH(TRIM('query (10)'!G6),Cleaning_Rules!$A$5:$A$10,0)),"UNKNOWN")) -> COMPLETED | M6: =IF('query (10)'!I6="","",'query (10)'!I6) -> Electrical | N6: =IF('query (10)'!O6="","",'query (10)'!O6) -> Inspection | O6: =IF('query (10)'!P6="","",'query (10)'!P6) -> Medium | P6: =IF('query (10)'!N6="","",'query (10)'!N6) -> Check rotation dresser sensor | Q6: =TRIM('query (10)'!N6) -> Check rotation dresser sensor | R6: =TRIM(UPPER('query (10)'!R6)) | S6: =TRIM(UPPER('query (10)'!S6)) | T6: =IF('query (10)'!Q6="","",TRIM(UPPER('query (10)'!Q6))) | U6: =IF('query (10)'!T6="","",'query (10)'!T6) -> 1 | V6: =IF('query (10)'!T6="","",IFERROR(VALUE('query (10)'!T6),"")) -> 1 | W6: =IF('query (10)'!U6="","",'query (10)'!U6) -> 0 | X6: =IF('query (10)'!V6="","",'query (10)'!V6) -> 90 | Y6: =IF('query (10)'!W6="","",'query (10)'!W6) -> 45919 | Z6: =IF('query (10)'!X6="","",'query (10)'!X6) -> 46090 | AA6: =IF('query (10)'!Y6="","",'query (10)'!Y6) -> 46090 | AB6: =IF('query (10)'!Z6="","",'query (10)'!Z6) -> 46180 | AC6: =IF(OR('query (10)'!AA6="",COUNTIF(Cleaning_Rules!$A$21:$A$26,TRIM('query (10)'!AA6))>0),"",TRIM('query (10)'!AA6)) | AD6: =IF('query (10)'!AB6="","",TRIM(IFERROR(_xlfn.TEXTBEFORE('query (10)'!AB6,"("),'query (10)'!AB6))) -> เริ่มซ่อมงาน PM แล้ว รับผิดชอบโดย NATDANAI JUTHATHEP | AE6: =IFERROR(LOWER(TRIM(_xlfn.TEXTBEFORE(_xlfn.TEXTAFTER('query (10)'!AB6,"("),")"))),"") -> juthathep-n-4697@nsk.com | AF6: =IF('query (10)'!AD6="","",TRIM('query (10)'!AD6)) -> ปิยะพงษ์ ทองแสน | AG6: =IF('query (10)'!AE6="","",TRIM('query (10)'!AE6)) -> ณัฐดนัย จุฑาเทพ | AH6: =IF('query (10)'!AF6="","",IFERROR(VALUE('query (10)'!AF6),"")) | AI6: =IF('query (10)'!AG6="","",TRIM('query (10)'!AG6)) | AJ6: =IF('query (10)'!AH6="","",IFERROR(VALUE('query (10)'!AH6),"")) | AK6: =IF('query (10)'!AI6="","",TRIM('query (10)'!AI6)) | AL6: =IF($Y6="","",YEAR($Y6)) -> 2025 | AM6: =IF($Y6="","",TEXT($Y6,"yyyy-mm")) -> 2025-09 | AN6: =IF(OR($AB6="",$L6="COMPLETED"),"",IF($AB6<TODAY(),"OVERDUE","ON_SCHEDULE")) | AO6: =_xlfn.TEXTJOIN(" | ",TRUE,$C6,$D6,$E6,$F6,$H6,$I6,$M6,$N6,$O6,$Q6,$R6,$S6,$T6,$AC6,$AD6,$AG6) -> GR-150 | OUTER RING RACEWAY SUPER FINISH M/C | BWD2 | DRESSER | Time-based Maintenance | Electrical | Inspection | Medium | Check rotation dresser sensor | เริ่มซ่อมงาน PM แล้ว รับผิดชอบโดย NATDANAI JUTHATHEP | ณัฐดนัย จุฑาเทพ | AP6: =_xlfn.TEXTJOIN("; ",TRUE,IF(COUNTA('query (10)'!A6:AK6)<=6,"NEAR_EMPTY_ROW",""),IF($K6="","MISSING_STATUS",""),IF(AND($K6="เสร็จสิ้น",$Z6=""),"DONE_NO_ACTUAL_DATE",""),IF(AND($I6="Condition-based Maintenance",$AH6=""),"CBM_NO_MEASUREMENT",""),IF(OR($X6="",$X6=0),"INVALID_PERIOD",""),IF(AND($AA6<>"",$AB6<>"",$AB6<$AA6),"DATE_SEQUENCE_ERROR",""),IF(AND($AB6<>"",$AB6>DATE(2030,12,31)),"DATE_OUTLIER",""),IF($C6="","MISSING_QRCODE",""),IF($J6="UNKNOWN","UNKNOWN_PM_TYPE",""),IF($L6="UNKNOWN","UNKNOWN_STATUS","")) | AQ6: =IF($W6="","",IF($W6>0,"YES","NO")) -> NO
A7: =IF('query (10)'!A7="","",'query (10)'!A7) -> 16 | B7: =IF('query (10)'!B7="","",'query (10)'!B7) | C7: =TRIM(UPPER('query (10)'!M7)) -> GR-150 | D7: =TRIM(UPPER(IFERROR(_xlfn.TEXTBEFORE('query (10)'!L7,"("),'query (10)'!L7))) -> OUTER RING RACEWAY SUPER FINISH M/C | E7: =IFERROR(TRIM(UPPER(_xlfn.TEXTBEFORE(_xlfn.TEXTAFTER('query (10)'!L7,"("),")"))),"") | F7: =TRIM('query (10)'!K7) -> BWD2 | G7: =IF('query (10)'!J7="","",'query (10)'!J7) -> Dresser | H7: =TRIM(UPPER('query (10)'!J7)) -> DRESSER | I7: =IF('query (10)'!F7="","",'query (10)'!F7) -> Time-based Maintenance | J7: =IF('query (10)'!F7="","",IFERROR(INDEX(Cleaning_Rules!$B$14:$B$17,MATCH(TRIM('query (10)'!F7),Cleaning_Rules!$A$14:$A$17,0)),"UNKNOWN")) -> TBM | K7: =IF('query (10)'!G7="","",'query (10)'!G7) -> เสร็จสิ้น | L7: =IF('query (10)'!G7="","MISSING",IFERROR(INDEX(Cleaning_Rules!$B$5:$B$10,MATCH(TRIM('query (10)'!G7),Cleaning_Rules!$A$5:$A$10,0)),"UNKNOWN")) -> COMPLETED | M7: =IF('query (10)'!I7="","",'query (10)'!I7) -> Mechanical | N7: =IF('query (10)'!O7="","",'query (10)'!O7) -> Inspection | O7: =IF('query (10)'!P7="","",'query (10)'!P7) -> Important | P7: =IF('query (10)'!N7="","",'query (10)'!N7) -> Check belt dresser | Q7: =TRIM('query (10)'!N7) -> Check belt dresser | R7: =TRIM(UPPER('query (10)'!R7)) | S7: =TRIM(UPPER('query (10)'!S7)) | T7: =IF('query (10)'!Q7="","",TRIM(UPPER('query (10)'!Q7))) | U7: =IF('query (10)'!T7="","",'query (10)'!T7) -> 1 | V7: =IF('query (10)'!T7="","",IFERROR(VALUE('query (10)'!T7),"")) -> 1 | W7: =IF('query (10)'!U7="","",'query (10)'!U7) -> 0 | X7: =IF('query (10)'!V7="","",'query (10)'!V7) -> 90 | Y7: =IF('query (10)'!W7="","",'query (10)'!W7) -> 45919 | Z7: =IF('query (10)'!X7="","",'query (10)'!X7) | AA7: =IF('query (10)'!Y7="","",'query (10)'!Y7) -> 45883 | AB7: =IF('query (10)'!Z7="","",'query (10)'!Z7) -> 45973 | AC7: =IF(OR('query (10)'!AA7="",COUNTIF(Cleaning_Rules!$A$21:$A$26,TRIM('query (10)'!AA7))>0),"",TRIM('query (10)'!AA7)) | AD7: =IF('query (10)'!AB7="","",TRIM(IFERROR(_xlfn.TEXTBEFORE('query (10)'!AB7,"("),'query (10)'!AB7))) | AE7: =IFERROR(LOWER(TRIM(_xlfn.TEXTBEFORE(_xlfn.TEXTAFTER('query (10)'!AB7,"("),")"))),"") | AF7: =IF('query (10)'!AD7="","",TRIM('query (10)'!AD7)) -> ปิยะพงษ์ ทองแสน | AG7: =IF('query (10)'!AE7="","",TRIM('query (10)'!AE7)) -> ณัฐดนัย จุฑาเทพ | AH7: =IF('query (10)'!AF7="","",IFERROR(VALUE('query (10)'!AF7),"")) | AI7: =IF('query (10)'!AG7="","",TRIM('query (10)'!AG7)) | AJ7: =IF('query (10)'!AH7="","",IFERROR(VALUE('query (10)'!AH7),"")) | AK7: =IF('query (10)'!AI7="","",TRIM('query (10)'!AI7)) | AL7: =IF($Y7="","",YEAR($Y7)) -> 2025 | AM7: =IF($Y7="","",TEXT($Y7,"yyyy-mm")) -> 2025-09 | AN7: =IF(OR($AB7="",$L7="COMPLETED"),"",IF($AB7<TODAY(),"OVERDUE","ON_SCHEDULE")) | AO7: =_xlfn.TEXTJOIN(" | ",TRUE,$C7,$D7,$E7,$F7,$H7,$I7,$M7,$N7,$O7,$Q7,$R7,$S7,$T7,$AC7,$AD7,$AG7) -> GR-150 | OUTER RING RACEWAY SUPER FINISH M/C | BWD2 | DRESSER | Time-based Maintenance | Mechanical | Inspection | Important | Check belt dresser | ณัฐดนัย จุฑาเทพ | AP7: =_xlfn.TEXTJOIN("; ",TRUE,IF(COUNTA('query (10)'!A7:AK7)<=6,"NEAR_EMPTY_ROW",""),IF($K7="","MISSING_STATUS",""),IF(AND($K7="เสร็จสิ้น",$Z7=""),"DONE_NO_ACTUAL_DATE",""),IF(AND($I7="Condition-based Maintenance",$AH7=""),"CBM_NO_MEASUREMENT",""),IF(OR($X7="",$X7=0),"INVALID_PERIOD",""),IF(AND($AA7<>"",$AB7<>"",$AB7<$AA7),"DATE_SEQUENCE_ERROR",""),IF(AND($AB7<>"",$AB7>DATE(2030,12,31)),"DATE_OUTLIER",""),IF($C7="","MISSING_QRCODE",""),IF($J7="UNKNOWN","UNKNOWN_PM_TYPE",""),IF($L7="UNKNOWN","UNKNOWN_STATUS","")) -> DONE_NO_ACTUAL_DATE | AQ7: =IF($W7="","",IF($W7>0,"YES","NO")) -> NO
A8: =IF('query (10)'!A8="","",'query (10)'!A8) -> 17 | B8: =IF('query (10)'!B8="","",'query (10)'!B8) -> 17223 | C8: =TRIM(UPPER('query (10)'!M8)) -> GR-150 | D8: =TRIM(UPPER(IFERROR(_xlfn.TEXTBEFORE('query (10)'!L8,"("),'query (10)'!L8))) -> OUTER RING RACEWAY SUPER FINISH M/C | E8: =IFERROR(TRIM(UPPER(_xlfn.TEXTBEFORE(_xlfn.TEXTAFTER('query (10)'!L8,"("),")"))),"") | F8: =TRIM('query (10)'!K8) -> BWD2 | G8: =IF('query (10)'!J8="","",'query (10)'!J8) -> Dresser | H8: =TRIM(UPPER('query (10)'!J8)) -> DRESSER | I8: =IF('query (10)'!F8="","",'query (10)'!F8) -> Time-based Maintenance | J8: =IF('query (10)'!F8="","",IFERROR(INDEX(Cleaning_Rules!$B$14:$B$17,MATCH(TRIM('query (10)'!F8),Cleaning_Rules!$A$14:$A$17,0)),"UNKNOWN")) -> TBM | K8: =IF('query (10)'!G8="","",'query (10)'!G8) -> เสร็จสิ้น | L8: =IF('query (10)'!G8="","MISSING",IFERROR(INDEX(Cleaning_Rules!$B$5:$B$10,MATCH(TRIM('query (10)'!G8),Cleaning_Rules!$A$5:$A$10,0)),"UNKNOWN")) -> COMPLETED | M8: =IF('query (10)'!I8="","",'query (10)'!I8) -> Mechanical | N8: =IF('query (10)'!O8="","",'query (10)'!O8) -> Measure | O8: =IF('query (10)'!P8="","",'query (10)'!P8) -> Urgent | P8: =IF('query (10)'!N8="","",'query (10)'!N8) -> Check accuracy of dresser unit | Q8: =TRIM('query (10)'!N8) -> Check accuracy of dresser unit | R8: =TRIM(UPPER('query (10)'!R8)) | S8: =TRIM(UPPER('query (10)'!S8)) | T8: =IF('query (10)'!Q8="","",TRIM(UPPER('query (10)'!Q8))) | U8: =IF('query (10)'!T8="","",'query (10)'!T8) -> 1 | V8: =IF('query (10)'!T8="","",IFERROR(VALUE('query (10)'!T8),"")) -> 1 | W8: =IF('query (10)'!U8="","",'query (10)'!U8) -> 0 | X8: =IF('query (10)'!V8="","",'query (10)'!V8) -> 90 | Y8: =IF('query (10)'!W8="","",'query (10)'!W8) -> 45919 | Z8: =IF('query (10)'!X8="","",'query (10)'!X8) -> 46031 | AA8: =IF('query (10)'!Y8="","",'query (10)'!Y8) -> 46031 | AB8: =IF('query (10)'!Z8="","",'query (10)'!Z8) -> 46121 | AC8: =IF(OR('query (10)'!AA8="",COUNTIF(Cleaning_Rules!$A$21:$A$26,TRIM('query (10)'!AA8))>0),"",TRIM('query (10)'!AA8)) | AD8: =IF('query (10)'!AB8="","",TRIM(IFERROR(_xlfn.TEXTBEFORE('query (10)'!AB8,"("),'query (10)'!AB8))) -> เริ่มซ่อมงาน PM แล้ว รับผิดชอบโดย PAHLA SEEDANG | AE8: =IFERROR(LOWER(TRIM(_xlfn.TEXTBEFORE(_xlfn.TEXTAFTER('query (10)'!AB8,"("),")"))),"") -> pahla@nsk.com | AF8: =IF('query (10)'!AD8="","",TRIM('query (10)'!AD8)) -> ปิยะพงษ์ ทองแสน | AG8: =IF('query (10)'!AE8="","",TRIM('query (10)'!AE8)) -> ณัฐดนัย จุฑาเทพ | AH8: =IF('query (10)'!AF8="","",IFERROR(VALUE('query (10)'!AF8),"")) | AI8: =IF('query (10)'!AG8="","",TRIM('query (10)'!AG8)) | AJ8: =IF('query (10)'!AH8="","",IFERROR(VALUE('query (10)'!AH8),"")) | AK8: =IF('query (10)'!AI8="","",TRIM('query (10)'!AI8)) | AL8: =IF($Y8="","",YEAR($Y8)) -> 2025 | AM8: =IF($Y8="","",TEXT($Y8,"yyyy-mm")) -> 2025-09 | AN8: =IF(OR($AB8="",$L8="COMPLETED"),"",IF($AB8<TODAY(),"OVERDUE","ON_SCHEDULE")) | AO8: =_xlfn.TEXTJOIN(" | ",TRUE,$C8,$D8,$E8,$F8,$H8,$I8,$M8,$N8,$O8,$Q8,$R8,$S8,$T8,$AC8,$AD8,$AG8) -> GR-150 | OUTER RING RACEWAY SUPER FINISH M/C | BWD2 | DRESSER | Time-based Maintenance | Mechanical | Measure | Urgent | Check accuracy of dresser unit | เริ่มซ่อมงาน PM แล้ว รับผิดชอบโดย PAHLA SEEDANG | ณัฐดนัย จุฑาเทพ | AP8: =_xlfn.TEXTJOIN("; ",TRUE,IF(COUNTA('query (10)'!A8:AK8)<=6,"NEAR_EMPTY_ROW",""),IF($K8="","MISSING_STATUS",""),IF(AND($K8="เสร็จสิ้น",$Z8=""),"DONE_NO_ACTUAL_DATE",""),IF(AND($I8="Condition-based Maintenance",$AH8=""),"CBM_NO_MEASUREMENT",""),IF(OR($X8="",$X8=0),"INVALID_PERIOD",""),IF(AND($AA8<>"",$AB8<>"",$AB8<$AA8),"DATE_SEQUENCE_ERROR",""),IF(AND($AB8<>"",$AB8>DATE(2030,12,31)),"DATE_OUTLIER",""),IF($C8="","MISSING_QRCODE",""),IF($J8="UNKNOWN","UNKNOWN_PM_TYPE",""),IF($L8="UNKNOWN","UNKNOWN_STATUS","")) | AQ8: =IF($W8="","",IF($W8>0,"YES","NO")) -> NO
A9: =IF('query (10)'!A9="","",'query (10)'!A9) -> 19 | B9: =IF('query (10)'!B9="","",'query (10)'!B9) | C9: =TRIM(UPPER('query (10)'!M9)) -> GR-062 | D9: =TRIM(UPPER(IFERROR(_xlfn.TEXTBEFORE('query (10)'!L9,"("),'query (10)'!L9))) -> INNER RING RACEWAY GRINDING M/C | E9: =IFERROR(TRIM(UPPER(_xlfn.TEXTBEFORE(_xlfn.TEXTAFTER('query (10)'!L9,"("),")"))),"") | F9: =TRIM('query (10)'!K9) -> BWD1 | G9: =IF('query (10)'!J9="","",'query (10)'!J9) -> Wheel Head | H9: =TRIM(UPPER('query (10)'!J9)) -> WHEEL HEAD | I9: =IF('query (10)'!F9="","",'query (10)'!F9) -> Time-based Maintenance | J9: =IF('query (10)'!F9="","",IFERROR(INDEX(Cleaning_Rules!$B$14:$B$17,MATCH(TRIM('query (10)'!F9),Cleaning_Rules!$A$14:$A$17,0)),"UNKNOWN")) -> TBM | K9: =IF('query (10)'!G9="","",'query (10)'!G9) -> แก้ไขแผน | L9: =IF('query (10)'!G9="","MISSING",IFERROR(INDEX(Cleaning_Rules!$B$5:$B$10,MATCH(TRIM('query (10)'!G9),Cleaning_Rules!$A$5:$A$10,0)),"UNKNOWN")) -> PLAN_REVISED | M9: =IF('query (10)'!I9="","",'query (10)'!I9) -> Electrical | N9: =IF('query (10)'!O9="","",'query (10)'!O9) -> Inspection | O9: =IF('query (10)'!P9="","",'query (10)'!P9) -> Medium | P9: =IF('query (10)'!N9="","",'query (10)'!N9) -> ตรวจสอบสายพาน Wheel head | Q9: =TRIM('query (10)'!N9) -> ตรวจสอบสายพาน Wheel head | R9: =TRIM(UPPER('query (10)'!R9)) -> WHEEL LUBRICATION TANK | S9: =TRIM(UPPER('query (10)'!S9)) -> 09-1020-0700-001C | T9: =IF('query (10)'!Q9="","",TRIM(UPPER('query (10)'!Q9))) -> MTMC-1441 | U9: =IF('query (10)'!T9="","",'query (10)'!T9) -> 1 | V9: =IF('query (10)'!T9="","",IFERROR(VALUE('query (10)'!T9),"")) -> 1 | W9: =IF('query (10)'!U9="","",'query (10)'!U9) -> 77600 | X9: =IF('query (10)'!V9="","",'query (10)'!V9) -> 180 | Y9: =IF('query (10)'!W9="","",'query (10)'!W9) -> 45931 | Z9: =IF('query (10)'!X9="","",'query (10)'!X9) | AA9: =IF('query (10)'!Y9="","",'query (10)'!Y9) -> 45931 | AB9: =IF('query (10)'!Z9="","",'query (10)'!Z9) -> 46111 | AC9: =IF(OR('query (10)'!AA9="",COUNTIF(Cleaning_Rules!$A$21:$A$26,TRIM('query (10)'!AA9))>0),"",TRIM('query (10)'!AA9)) | AD9: =IF('query (10)'!AB9="","",TRIM(IFERROR(_xlfn.TEXTBEFORE('query (10)'!AB9,"("),'query (10)'!AB9))) | AE9: =IFERROR(LOWER(TRIM(_xlfn.TEXTBEFORE(_xlfn.TEXTAFTER('query (10)'!AB9,"("),")"))),"") | AF9: =IF('query (10)'!AD9="","",TRIM('query (10)'!AD9)) -> ปิยะพงษ์ ทองแสน | AG9: =IF('query (10)'!AE9="","",TRIM('query (10)'!AE9)) -> ปิยะพงษ์ ทองแสน | AH9: =IF('query (10)'!AF9="","",IFERROR(VALUE('query (10)'!AF9),"")) | AI9: =IF('query (10)'!AG9="","",TRIM('query (10)'!AG9)) | AJ9: =IF('query (10)'!AH9="","",IFERROR(VALUE('query (10)'!AH9),"")) | AK9: =IF('query (10)'!AI9="","",TRIM('query (10)'!AI9)) | AL9: =IF($Y9="","",YEAR($Y9)) -> 2025 | AM9: =IF($Y9="","",TEXT($Y9,"yyyy-mm")) -> 2025-10 | AN9: =IF(OR($AB9="",$L9="COMPLETED"),"",IF($AB9<TODAY(),"OVERDUE","ON_SCHEDULE")) -> OVERDUE | AO9: =_xlfn.TEXTJOIN(" | ",TRUE,$C9,$D9,$E9,$F9,$H9,$I9,$M9,$N9,$O9,$Q9,$R9,$S9,$T9,$AC9,$AD9,$AG9) -> GR-062 | INNER RING RACEWAY GRINDING M/C | BWD1 | WHEEL HEAD | Time-based Maintenance | Electrical | Inspection | Medium | ตรวจสอบสายพาน Wheel head | WHEEL LUBRICATION TANK | 09-1020-0700-001C | MTMC-1441 | ปิยะพงษ์ ทองแสน | AP9: =_xlfn.TEXTJOIN("; ",TRUE,IF(COUNTA('query (10)'!A9:AK9)<=6,"NEAR_EMPTY_ROW",""),IF($K9="","MISSING_STATUS",""),IF(AND($K9="เสร็จสิ้น",$Z9=""),"DONE_NO_ACTUAL_DATE",""),IF(AND($I9="Condition-based Maintenance",$AH9=""),"CBM_NO_MEASUREMENT",""),IF(OR($X9="",$X9=0),"INVALID_PERIOD",""),IF(AND($AA9<>"",$AB9<>"",$AB9<$AA9),"DATE_SEQUENCE_ERROR",""),IF(AND($AB9<>"",$AB9>DATE(2030,12,31)),"DATE_OUTLIER",""),IF($C9="","MISSING_QRCODE",""),IF($J9="UNKNOWN","UNKNOWN_PM_TYPE",""),IF($L9="UNKNOWN","UNKNOWN_STATUS","")) | AQ9: =IF($W9="","",IF($W9>0,"YES","NO")) -> YES
A10: =IF('query (10)'!A10="","",'query (10)'!A10) -> 20 | B10: =IF('query (10)'!B10="","",'query (10)'!B10) | C10: =TRIM(UPPER('query (10)'!M10)) -> GR-062 | D10: =TRIM(UPPER(IFERROR(_xlfn.TEXTBEFORE('query (10)'!L10,"("),'query (10)'!L10))) -> INNER RING RACEWAY GRINDING M/C | E10: =IFERROR(TRIM(UPPER(_xlfn.TEXTBEFORE(_xlfn.TEXTAFTER('query (10)'!L10,"("),")"))),"") | F10: =TRIM('query (10)'!K10) -> BWD1 | G10: =IF('query (10)'!J10="","",'query (10)'!J10) -> Transfer | H10: =TRIM(UPPER('query (10)'!J10)) -> TRANSFER | I10: =IF('query (10)'!F10="","",'query (10)'!F10) -> Time-based Maintenance | J10: =IF('query (10)'!F10="","",IFERROR(INDEX(Cleaning_Rules!$B$14:$B$17,MATCH(TRIM('query (10)'!F10),Cleaning_Rules!$A$14:$A$17,0)),"UNKNOWN")) -> TBM | K10: =IF('query (10)'!G10="","",'query (10)'!G10) -> แก้ไขแผน | L10: =IF('query (10)'!G10="","MISSING",IFERROR(INDEX(Cleaning_Rules!$B$5:$B$10,MATCH(TRIM('query (10)'!G10),Cleaning_Rules!$A$5:$A$10,0)),"UNKNOWN")) -> PLAN_REVISED | M10: =IF('query (10)'!I10="","",'query (10)'!I10) -> Electrical | N10: =IF('query (10)'!O10="","",'query (10)'!O10) -> Inspection | O10: =IF('query (10)'!P10="","",'query (10)'!P10) -> Important | P10: =IF('query (10)'!N10="","",'query (10)'!N10) -> ตรวจสอบเซ็นเซอร์ Up down | Q10: =TRIM('query (10)'!N10) -> ตรวจสอบเซ็นเซอร์ Up down | R10: =TRIM(UPPER('query (10)'!R10)) -> SENSOR | S10: =TRIM(UPPER('query (10)'!S10)) -> D-M9BAL | T10: =IF('query (10)'!Q10="","",TRIM(UPPER('query (10)'!Q10))) -> MTEE-0725 | U10: =IF('query (10)'!T10="","",'query (10)'!T10) -> 1 | V10: =IF('query (10)'!T10="","",IFERROR(VALUE('query (10)'!T10),"")) -> 1 | W10: =IF('query (10)'!U10="","",'query (10)'!U10) -> 797.64 | X10: =IF('query (10)'!V10="","",'query (10)'!V10) -> 180 | Y10: =IF('query (10)'!W10="","",'query (10)'!W10) -> 45932 | Z10: =IF('query (10)'!X10="","",'query (10)'!X10) | AA10: =IF('query (10)'!Y10="","",'query (10)'!Y10) -> 45932 | AB10: =IF('query (10)'!Z10="","",'query (10)'!Z10) -> 46112 | AC10: =IF(OR('query (10)'!AA10="",COUNTIF(Cleaning_Rules!$A$21:$A$26,TRIM('query (10)'!AA10))>0),"",TRIM('query (10)'!AA10)) | AD10: =IF('query (10)'!AB10="","",TRIM(IFERROR(_xlfn.TEXTBEFORE('query (10)'!AB10,"("),'query (10)'!AB10))) | AE10: =IFERROR(LOWER(TRIM(_xlfn.TEXTBEFORE(_xlfn.TEXTAFTER('query (10)'!AB10,"("),")"))),"") | AF10: =IF('query (10)'!AD10="","",TRIM('query (10)'!AD10)) -> อัมรินทร์ รักษาพล | AG10: =IF('query (10)'!AE10="","",TRIM('query (10)'!AE10)) -> พงษ์พิทักษ์ ศรไชย | AH10: =IF('query (10)'!AF10="","",IFERROR(VALUE('query (10)'!AF10),"")) | AI10: =IF('query (10)'!AG10="","",TRIM('query (10)'!AG10)) | AJ10: =IF('query (10)'!AH10="","",IFERROR(VALUE('query (10)'!AH10),"")) | AK10: =IF('query (10)'!AI10="","",TRIM('query (10)'!AI10)) | AL10: =IF($Y10="","",YEAR($Y10)) -> 2025 | AM10: =IF($Y10="","",TEXT($Y10,"yyyy-mm")) -> 2025-10 | AN10: =IF(OR($AB10="",$L10="COMPLETED"),"",IF($AB10<TODAY(),"OVERDUE","ON_SCHEDULE")) -> OVERDUE | AO10: =_xlfn.TEXTJOIN(" | ",TRUE,$C10,$D10,$E10,$F10,$H10,$I10,$M10,$N10,$O10,$Q10,$R10,$S10,$T10,$AC10,$AD10,$AG10) -> GR-062 | INNER RING RACEWAY GRINDING M/C | BWD1 | TRANSFER | Time-based Maintenance | Electrical | Inspection | Important | ตรวจสอบเซ็นเซอร์ Up down | SENSOR | D-M9BAL | MTEE-0725 | พงษ์พิทักษ์ ศรไชย | AP10: =_xlfn.TEXTJOIN("; ",TRUE,IF(COUNTA('query (10)'!A10:AK10)<=6,"NEAR_EMPTY_ROW",""),IF($K10="","MISSING_STATUS",""),IF(AND($K10="เสร็จสิ้น",$Z10=""),"DONE_NO_ACTUAL_DATE",""),IF(AND($I10="Condition-based Maintenance",$AH10=""),"CBM_NO_MEASUREMENT",""),IF(OR($X10="",$X10=0),"INVALID_PERIOD",""),IF(AND($AA10<>"",$AB10<>"",$AB10<$AA10),"DATE_SEQUENCE_ERROR",""),IF(AND($AB10<>"",$AB10>DATE(2030,12,31)),"DATE_OUTLIER",""),IF($C10="","MISSING_QRCODE",""),IF($J10="UNKNOWN","UNKNOWN_PM_TYPE",""),IF($L10="UNKNOWN","UNKNOWN_STATUS","")) | AQ10: =IF($W10="","",IF($W10>0,"YES","NO")) -> YES
A11: =IF('query (10)'!A11="","",'query (10)'!A11) -> 21 | B11: =IF('query (10)'!B11="","",'query (10)'!B11) | C11: =TRIM(UPPER('query (10)'!M11)) -> GR-721 | D11: =TRIM(UPPER(IFERROR(_xlfn.TEXTBEFORE('query (10)'!L11,"("),'query (10)'!L11))) -> OUTER RING RACEWAY GRINDING MACHINE. | E11: =IFERROR(TRIM(UPPER(_xlfn.TEXTBEFORE(_xlfn.TEXTAFTER('query (10)'!L11,"("),")"))),"") | F11: =TRIM('query (10)'!K11) -> MCB3 | G11: =IF('query (10)'!J11="","",'query (10)'!J11) -> Conveyor | H11: =TRIM(UPPER('query (10)'!J11)) -> CONVEYOR | I11: =IF('query (10)'!F11="","",'query (10)'!F11) -> Time-based Maintenance | J11: =IF('query (10)'!F11="","",IFERROR(INDEX(Cleaning_Rules!$B$14:$B$17,MATCH(TRIM('query (10)'!F11),Cleaning_Rules!$A$14:$A$17,0)),"UNKNOWN")) -> TBM | K11: =IF('query (10)'!G11="","",'query (10)'!G11) -> เสร็จสิ้น | L11: =IF('query (10)'!G11="","MISSING",IFERROR(INDEX(Cleaning_Rules!$B$5:$B$10,MATCH(TRIM('query (10)'!G11),Cleaning_Rules!$A$5:$A$10,0)),"UNKNOWN")) -> COMPLETED | M11: =IF('query (10)'!I11="","",'query (10)'!I11) -> Mechanical | N11: =IF('query (10)'!O11="","",'query (10)'!O11) -> Measure | O11: =IF('query (10)'!P11="","",'query (10)'!P11) -> Urgent | P11: =IF('query (10)'!N11="","",'query (10)'!N11) -> High Velocity Vibration of Work head unit 5.00 mm/s | Q11: =TRIM('query (10)'!N11) -> High Velocity Vibration of Work head unit 5.00 mm/s | R11: =TRIM(UPPER('query (10)'!R11)) -> ACCELERROMETER | S11: =TRIM(UPPER('query (10)'!S11)) -> 7201-50 | T11: =IF('query (10)'!Q11="","",TRIM(UPPER('query (10)'!Q11))) -> MTEE-0003 | U11: =IF('query (10)'!T11="","",'query (10)'!T11) -> 1 | V11: =IF('query (10)'!T11="","",IFERROR(VALUE('query (10)'!T11),"")) -> 1 | W11: =IF('query (10)'!U11="","",'query (10)'!U11) -> 48000 | X11: =IF('query (10)'!V11="","",'query (10)'!V11) -> 60 | Y11: =IF('query (10)'!W11="","",'query (10)'!W11) -> 45902 | Z11: =IF('query (10)'!X11="","",'query (10)'!X11) | AA11: =IF('query (10)'!Y11="","",'query (10)'!Y11) -> 45931 | AB11: =IF('query (10)'!Z11="","",'query (10)'!Z11) -> 45991 | AC11: =IF(OR('query (10)'!AA11="",COUNTIF(Cleaning_Rules!$A$21:$A$26,TRIM('query (10)'!AA11))>0),"",TRIM('query (10)'!AA11)) -> test | AD11: =IF('query (10)'!AB11="","",TRIM(IFERROR(_xlfn.TEXTBEFORE('query (10)'!AB11,"("),'query (10)'!AB11))) | AE11: =IFERROR(LOWER(TRIM(_xlfn.TEXTBEFORE(_xlfn.TEXTAFTER('query (10)'!AB11,"("),")"))),"") | AF11: =IF('query (10)'!AD11="","",TRIM('query (10)'!AD11)) -> ภูชิต กุลเสรี | AG11: =IF('query (10)'!AE11="","",TRIM('query (10)'!AE11)) -> จักรภัทร โคตรสมบัติ | AH11: =IF('query (10)'!AF11="","",IFERROR(VALUE('query (10)'!AF11),"")) | AI11: =IF('query (10)'!AG11="","",TRIM('query (10)'!AG11)) | AJ11: =IF('query (10)'!AH11="","",IFERROR(VALUE('query (10)'!AH11),"")) | AK11: =IF('query (10)'!AI11="","",TRIM('query (10)'!AI11)) | AL11: =IF($Y11="","",YEAR($Y11)) -> 2025 | AM11: =IF($Y11="","",TEXT($Y11,"yyyy-mm")) -> 2025-09 | AN11: =IF(OR($AB11="",$L11="COMPLETED"),"",IF($AB11<TODAY(),"OVERDUE","ON_SCHEDULE")) | AO11: =_xlfn.TEXTJOIN(" | ",TRUE,$C11,$D11,$E11,$F11,$H11,$I11,$M11,$N11,$O11,$Q11,$R11,$S11,$T11,$AC11,$AD11,$AG11) -> GR-721 | OUTER RING RACEWAY GRINDING MACHINE. | MCB3 | CONVEYOR | Time-based Maintenance | Mechanical | Measure | Urgent | High Velocity Vibration of Work head unit 5.00 mm/s | ACCELERROMETER | 7201-50 | MTEE-0003 | test | จักรภัทร โคตรสมบัติ | AP11: =_xlfn.TEXTJOIN("; ",TRUE,IF(COUNTA('query (10)'!A11:AK11)<=6,"NEAR_EMPTY_ROW",""),IF($K11="","MISSING_STATUS",""),IF(AND($K11="เสร็จสิ้น",$Z11=""),"DONE_NO_ACTUAL_DATE",""),IF(AND($I11="Condition-based Maintenance",$AH11=""),"CBM_NO_MEASUREMENT",""),IF(OR($X11="",$X11=0),"INVALID_PERIOD",""),IF(AND($AA11<>"",$AB11<>"",$AB11<$AA11),"DATE_SEQUENCE_ERROR",""),IF(AND($AB11<>"",$AB11>DATE(2030,12,31)),"DATE_OUTLIER",""),IF($C11="","MISSING_QRCODE",""),IF($J11="UNKNOWN","UNKNOWN_PM_TYPE",""),IF($L11="UNKNOWN","UNKNOWN_STATUS","")) -> DONE_NO_ACTUAL_DATE | AQ11: =IF($W11="","",IF($W11>0,"YES","NO")) -> YES
A12: =IF('query (10)'!A12="","",'query (10)'!A12) -> 22 | B12: =IF('query (10)'!B12="","",'query (10)'!B12) | C12: =TRIM(UPPER('query (10)'!M12)) -> GR-150 | D12: =TRIM(UPPER(IFERROR(_xlfn.TEXTBEFORE('query (10)'!L12,"("),'query (10)'!L12))) -> OUTER RING RACEWAY SUPER FINISH M/C | E12: =IFERROR(TRIM(UPPER(_xlfn.TEXTBEFORE(_xlfn.TEXTAFTER('query (10)'!L12,"("),")"))),"") | F12: =TRIM('query (10)'!K12) -> BWD2 | G12: =IF('query (10)'!J12="","",'query (10)'!J12) -> Conveyor | H12: =TRIM(UPPER('query (10)'!J12)) -> CONVEYOR | I12: =IF('query (10)'!F12="","",'query (10)'!F12) -> Time-based Maintenance | J12: =IF('query (10)'!F12="","",IFERROR(INDEX(Cleaning_Rules!$B$14:$B$17,MATCH(TRIM('query (10)'!F12),Cleaning_Rules!$A$14:$A$17,0)),"UNKNOWN")) -> TBM | K12: =IF('query (10)'!G12="","",'query (10)'!G12) -> เสร็จสิ้น | L12: =IF('query (10)'!G12="","MISSING",IFERROR(INDEX(Cleaning_Rules!$B$5:$B$10,MATCH(TRIM('query (10)'!G12),Cleaning_Rules!$A$5:$A$10,0)),"UNKNOWN")) -> COMPLETED | M12: =IF('query (10)'!I12="","",'query (10)'!I12) -> Electrical | N12: =IF('query (10)'!O12="","",'query (10)'!O12) -> Inspection | O12: =IF('query (10)'!P12="","",'query (10)'!P12) -> Medium | P12: =IF('query (10)'!N12="","",'query (10)'!N12) -> test | Q12: =TRIM('query (10)'!N12) -> test | R12: =TRIM(UPPER('query (10)'!R12)) -> AMP METER | S12: =TRIM(UPPER('query (10)'!S12)) -> ACF-85P(RANGE 0-50AMP) | T12: =IF('query (10)'!Q12="","",TRIM(UPPER('query (10)'!Q12))) -> MTEE-0014 | U12: =IF('query (10)'!T12="","",'query (10)'!T12) -> 1 | V12: =IF('query (10)'!T12="","",IFERROR(VALUE('query (10)'!T12),"")) -> 1 | W12: =IF('query (10)'!U12="","",'query (10)'!U12) -> 2726.5 | X12: =IF('query (10)'!V12="","",'query (10)'!V12) -> 60 | Y12: =IF('query (10)'!W12="","",'query (10)'!W12) -> 45933 | Z12: =IF('query (10)'!X12="","",'query (10)'!X12) | AA12: =IF('query (10)'!Y12="","",'query (10)'!Y12) -> 45902 | AB12: =IF('query (10)'!Z12="","",'query (10)'!Z12) -> 45962 | AC12: =IF(OR('query (10)'!AA12="",COUNTIF(Cleaning_Rules!$A$21:$A$26,TRIM('query (10)'!AA12))>0),"",TRIM('query (10)'!AA12)) -> test | AD12: =IF('query (10)'!AB12="","",TRIM(IFERROR(_xlfn.TEXTBEFORE('query (10)'!AB12,"("),'query (10)'!AB12))) | AE12: =IFERROR(LOWER(TRIM(_xlfn.TEXTBEFORE(_xlfn.TEXTAFTER('query (10)'!AB12,"("),")"))),"") | AF12: =IF('query (10)'!AD12="","",TRIM('query (10)'!AD12)) -> ปิยะพงษ์ ทองแสน | AG12: =IF('query (10)'!AE12="","",TRIM('query (10)'!AE12)) -> ปิยะพงษ์ ทองแสน | AH12: =IF('query (10)'!AF12="","",IFERROR(VALUE('query (10)'!AF12),"")) | AI12: =IF('query (10)'!AG12="","",TRIM('query (10)'!AG12)) | AJ12: =IF('query (10)'!AH12="","",IFERROR(VALUE('query (10)'!AH12),"")) | AK12: =IF('query (10)'!AI12="","",TRIM('query (10)'!AI12)) | AL12: =IF($Y12="","",YEAR($Y12)) -> 2025 | AM12: =IF($Y12="","",TEXT($Y12,"yyyy-mm")) -> 2025-10 | AN12: =IF(OR($AB12="",$L12="COMPLETED"),"",IF($AB12<TODAY(),"OVERDUE","ON_SCHEDULE")) | AO12: =_xlfn.TEXTJOIN(" | ",TRUE,$C12,$D12,$E12,$F12,$H12,$I12,$M12,$N12,$O12,$Q12,$R12,$S12,$T12,$AC12,$AD12,$AG12) -> GR-150 | OUTER RING RACEWAY SUPER FINISH M/C | BWD2 | CONVEYOR | Time-based Maintenance | Electrical | Inspection | Medium | test | AMP METER | ACF-85P(RANGE 0-50AMP) | MTEE-0014 | test | ปิยะพงษ์ ทองแสน | AP12: =_xlfn.TEXTJOIN("; ",TRUE,IF(COUNTA('query (10)'!A12:AK12)<=6,"NEAR_EMPTY_ROW",""),IF($K12="","MISSING_STATUS",""),IF(AND($K12="เสร็จสิ้น",$Z12=""),"DONE_NO_ACTUAL_DATE",""),IF(AND($I12="Condition-based Maintenance",$AH12=""),"CBM_NO_MEASUREMENT",""),IF(OR($X12="",$X12=0),"INVALID_PERIOD",""),IF(AND($AA12<>"",$AB12<>"",$AB12<$AA12),"DATE_SEQUENCE_ERROR",""),IF(AND($AB12<>"",$AB12>DATE(2030,12,31)),"DATE_OUTLIER",""),IF($C12="","MISSING_QRCODE",""),IF($J12="UNKNOWN","UNKNOWN_PM_TYPE",""),IF($L12="UNKNOWN","UNKNOWN_STATUS","")) -> DONE_NO_ACTUAL_DATE | AQ12: =IF($W12="","",IF($W12>0,"YES","NO")) -> YES
A13: =IF('query (10)'!A13="","",'query (10)'!A13) -> 23 | B13: =IF('query (10)'!B13="","",'query (10)'!B13) | C13: =TRIM(UPPER('query (10)'!M13)) -> GR-150 | D13: =TRIM(UPPER(IFERROR(_xlfn.TEXTBEFORE('query (10)'!L13,"("),'query (10)'!L13))) -> OUTER RING RACEWAY SUPER FINISH M/C | E13: =IFERROR(TRIM(UPPER(_xlfn.TEXTBEFORE(_xlfn.TEXTAFTER('query (10)'!L13,"("),")"))),"") | F13: =TRIM('query (10)'!K13) -> BWD2 | G13: =IF('query (10)'!J13="","",'query (10)'!J13) -> Dresser | H13: =TRIM(UPPER('query (10)'!J13)) -> DRESSER | I13: =IF('query (10)'!F13="","",'query (10)'!F13) -> Time-based Maintenance | J13: =IF('query (10)'!F13="","",IFERROR(INDEX(Cleaning_Rules!$B$14:$B$17,MATCH(TRIM('query (10)'!F13),Cleaning_Rules!$A$14:$A$17,0)),"UNKNOWN")) -> TBM | K13: =IF('query (10)'!G13="","",'query (10)'!G13) -> เสร็จสิ้น | L13: =IF('query (10)'!G13="","MISSING",IFERROR(INDEX(Cleaning_Rules!$B$5:$B$10,MATCH(TRIM('query (10)'!G13),Cleaning_Rules!$A$5:$A$10,0)),"UNKNOWN")) -> COMPLETED | M13: =IF('query (10)'!I13="","",'query (10)'!I13) -> Electrical | N13: =IF('query (10)'!O13="","",'query (10)'!O13) -> Inspection | O13: =IF('query (10)'!P13="","",'query (10)'!P13) -> Medium | P13: =IF('query (10)'!N13="","",'query (10)'!N13) -> ตรวจสอบ Dresser | Q13: =TRIM('query (10)'!N13) -> ตรวจสอบ Dresser | R13: =TRIM(UPPER('query (10)'!R13)) -> DRESS SPINDLE | S13: =TRIM(UPPER('query (10)'!S13)) -> UID201 | T13: =IF('query (10)'!Q13="","",TRIM(UPPER('query (10)'!Q13))) -> MTMC-1479 | U13: =IF('query (10)'!T13="","",'query (10)'!T13) -> 1 | V13: =IF('query (10)'!T13="","",IFERROR(VALUE('query (10)'!T13),"")) -> 1 | W13: =IF('query (10)'!U13="","",'query (10)'!U13) -> 340335.66 | X13: =IF('query (10)'!V13="","",'query (10)'!V13) -> 60 | Y13: =IF('query (10)'!W13="","",'query (10)'!W13) -> 45933 | Z13: =IF('query (10)'!X13="","",'query (10)'!X13) | AA13: =IF('query (10)'!Y13="","",'query (10)'!Y13) -> 45902 | AB13: =IF('query (10)'!Z13="","",'query (10)'!Z13) -> 45962 | AC13: =IF(OR('query (10)'!AA13="",COUNTIF(Cleaning_Rules!$A$21:$A$26,TRIM('query (10)'!AA13))>0),"",TRIM('query (10)'!AA13)) -> tes | AD13: =IF('query (10)'!AB13="","",TRIM(IFERROR(_xlfn.TEXTBEFORE('query (10)'!AB13,"("),'query (10)'!AB13))) | AE13: =IFERROR(LOWER(TRIM(_xlfn.TEXTBEFORE(_xlfn.TEXTAFTER('query (10)'!AB13,"("),")"))),"") | AF13: =IF('query (10)'!AD13="","",TRIM('query (10)'!AD13)) -> ปิยะพงษ์ ทองแสน | AG13: =IF('query (10)'!AE13="","",TRIM('query (10)'!AE13)) -> ปิยะพงษ์ ทองแสน | AH13: =IF('query (10)'!AF13="","",IFERROR(VALUE('query (10)'!AF13),"")) | AI13: =IF('query (10)'!AG13="","",TRIM('query (10)'!AG13)) | AJ13: =IF('query (10)'!AH13="","",IFERROR(VALUE('query (10)'!AH13),"")) | AK13: =IF('query (10)'!AI13="","",TRIM('query (10)'!AI13)) | AL13: =IF($Y13="","",YEAR($Y13)) -> 2025 | AM13: =IF($Y13="","",TEXT($Y13,"yyyy-mm")) -> 2025-10 | AN13: =IF(OR($AB13="",$L13="COMPLETED"),"",IF($AB13<TODAY(),"OVERDUE","ON_SCHEDULE")) | AO13: =_xlfn.TEXTJOIN(" | ",TRUE,$C13,$D13,$E13,$F13,$H13,$I13,$M13,$N13,$O13,$Q13,$R13,$S13,$T13,$AC13,$AD13,$AG13) -> GR-150 | OUTER RING RACEWAY SUPER FINISH M/C | BWD2 | DRESSER | Time-based Maintenance | Electrical | Inspection | Medium | ตรวจสอบ Dresser | DRESS SPINDLE | UID201 | MTMC-1479 | tes | ปิยะพงษ์ ทองแสน | AP13: =_xlfn.TEXTJOIN("; ",TRUE,IF(COUNTA('query (10)'!A13:AK13)<=6,"NEAR_EMPTY_ROW",""),IF($K13="","MISSING_STATUS",""),IF(AND($K13="เสร็จสิ้น",$Z13=""),"DONE_NO_ACTUAL_DATE",""),IF(AND($I13="Condition-based Maintenance",$AH13=""),"CBM_NO_MEASUREMENT",""),IF(OR($X13="",$X13=0),"INVALID_PERIOD",""),IF(AND($AA13<>"",$AB13<>"",$AB13<$AA13),"DATE_SEQUENCE_ERROR",""),IF(AND($AB13<>"",$AB13>DATE(2030,12,31)),"DATE_OUTLIER",""),IF($C13="","MISSING_QRCODE",""),IF($J13="UNKNOWN","UNKNOWN_PM_TYPE",""),IF($L13="UNKNOWN","UNKNOWN_STATUS","")) -> DONE_NO_ACTUAL_DATE | AQ13: =IF($W13="","",IF($W13>0,"YES","NO")) -> YES
... A2821: =IF('query (10)'!A2821="","",'query (10)'!A2821) -> 3084 | B2821: =IF('query (10)'!B2821="","",'query (10)'!B2821) | C2821: =TRIM(UPPER('query (10)'!M2821)) -> GR-922 | D2821: =TRIM(UPPER(IFERROR(_xlfn.TEXTBEFORE('query (10)'!L2821,"("),'query (10)'!L2821))) -> OUTER RING RACEWAY GRINDING M/C | E2821: =IFERROR(TRIM(UPPER(_xlfn.TEXTBEFORE(_xlfn.TEXTAFTER('query (10)'!L2821,"("),")"))),"") | F2821: =TRIM('query (10)'!K2821) -> WP Grinding3 | G2821: =IF('query (10)'!J2821="","",'query (10)'!J2821) -> AG | H2821: =TRIM(UPPER('query (10)'!J2821)) -> AG | I2821: =IF('query (10)'!F2821="","",'query (10)'!F2821) -> Time-based Maintenance | J2821: =IF('query (10)'!F2821="","",IFERROR(INDEX(Cleaning_Rules!$B$14:$B$17,MATCH(TRIM('query (10)'!F2821),Cleaning_Rules!$A$14:$A$17,0)),"UNKNOWN")) -> TBM | K2821: =IF('query (10)'!G2821="","",'query (10)'!G2821) -> แผนใหม่ | L2821: =IF('query (10)'!G2821="","MISSING",IFERROR(INDEX(Cleaning_Rules!$B$5:$B$10,MATCH(TRIM('query (10)'!G2821),Cleaning_Rules!$A$5:$A$10,0)),"UNKNOWN")) -> NEW_PLAN | M2821: =IF('query (10)'!I2821="","",'query (10)'!I2821) -> Mechanical | N2821: =IF('query (10)'!O2821="","",'query (10)'!O2821) -> Part Change | O2821: =IF('query (10)'!P2821="","",'query (10)'!P2821) -> Medium | P2821: =IF('query (10)'!N2821="","",'query (10)'!N2821) -> Out chute plate มีรอยสึกหรอ เวลาที่ชิ้นงานโหลดออกมา ทำให้ชิ้นงานติดขัด | Q2821: =TRIM('query (10)'!N2821) -> Out chute plate มีรอยสึกหรอ เวลาที่ชิ้นงานโหลดออกมา ทำให้ชิ้นงานติดขัด | R2821: =TRIM(UPPER('query (10)'!R2821)) | S2821: =TRIM(UPPER('query (10)'!S2821)) | T2821: =IF('query (10)'!Q2821="","",TRIM(UPPER('query (10)'!Q2821))) | U2821: =IF('query (10)'!T2821="","",'query (10)'!T2821) | V2821: =IF('query (10)'!T2821="","",IFERROR(VALUE('query (10)'!T2821),"")) | W2821: =IF('query (10)'!U2821="","",'query (10)'!U2821) -> 0 | X2821: =IF('query (10)'!V2821="","",'query (10)'!V2821) -> 0 | Y2821: =IF('query (10)'!W2821="","",'query (10)'!W2821) -> 46203 | Z2821: =IF('query (10)'!X2821="","",'query (10)'!X2821) | AA2821: =IF('query (10)'!Y2821="","",'query (10)'!Y2821) -> 46203 | AB2821: =IF('query (10)'!Z2821="","",'query (10)'!Z2821) -> 46203 | AC2821: =IF(OR('query (10)'!AA2821="",COUNTIF(Cleaning_Rules!$A$21:$A$26,TRIM('query (10)'!AA2821))>0),"",TRIM('query (10)'!AA2821)) | AD2821: =IF('query (10)'!AB2821="","",TRIM(IFERROR(_xlfn.TEXTBEFORE('query (10)'!AB2821,"("),'query (10)'!AB2821))) | AE2821: =IFERROR(LOWER(TRIM(_xlfn.TEXTBEFORE(_xlfn.TEXTAFTER('query (10)'!AB2821,"("),")"))),"") | AF2821: =IF('query (10)'!AD2821="","",TRIM('query (10)'!AD2821)) -> เจษฎา ผิวบาง | AG2821: =IF('query (10)'!AE2821="","",TRIM('query (10)'!AE2821)) -> เจษฎา ผิวบาง | AH2821: =IF('query (10)'!AF2821="","",IFERROR(VALUE('query (10)'!AF2821),"")) | AI2821: =IF('query (10)'!AG2821="","",TRIM('query (10)'!AG2821)) | AJ2821: =IF('query (10)'!AH2821="","",IFERROR(VALUE('query (10)'!AH2821),"")) | AK2821: =IF('query (10)'!AI2821="","",TRIM('query (10)'!AI2821)) | AL2821: =IF($Y2821="","",YEAR($Y2821)) -> 2026 | AM2821: =IF($Y2821="","",TEXT($Y2821,"yyyy-mm")) -> 2026-06 | AN2821: =IF(OR($AB2821="",$L2821="COMPLETED"),"",IF($AB2821<TODAY(),"OVERDUE","ON_SCHEDULE")) -> OVERDUE | AO2821: =_xlfn.TEXTJOIN(" | ",TRUE,$C2821,$D2821,$E2821,$F2821,$H2821,$I2821,$M2821,$N2821,$O2821,$Q2821,$R2821,$S2821,$T2821,$AC2821,$AD2821,$AG2821) -> GR-922 | OUTER RING RACEWAY GRINDING M/C | WP Grinding3 | AG | Time-based Maintenance | Mechanical | Part Change | Medium | Out chute plate มีรอยสึกหรอ เวลาที่ชิ้นงานโหลดออกมา ทำให้ชิ้นงานติดขัด | เจษฎา ผิวบาง | AP2821: =_xlfn.TEXTJOIN("; ",TRUE,IF(COUNTA('query (10)'!A2821:AK2821)<=6,"NEAR_EMPTY_ROW",""),IF($K2821="","MISSING_STATUS",""),IF(AND($K2821="เสร็จสิ้น",$Z2821=""),"DONE_NO_ACTUAL_DATE",""),IF(AND($I2821="Condition-based Maintenance",$AH2821=""),"CBM_NO_MEASUREMENT",""),IF(OR($X2821="",$X2821=0),"INVALID_PERIOD",""),IF(AND($AA2821<>"",$AB2821<>"",$AB2821<$AA2821),"DATE_SEQUENCE_ERROR",""),IF(AND($AB2821<>"",$AB2821>DATE(2030,12,31)),"DATE_OUTLIER",""),IF($C2821="","MISSING_QRCODE",""),IF($J2821="UNKNOWN","UNKNOWN_PM_TYPE",""),IF($L2821="UNKNOWN","UNKNOWN_STATUS","")) -> INVALID_PERIOD | AQ2821: =IF($W2821="","",IF($W2821>0,"YES","NO")) -> NO

Sheet Data_Readiness
A1: รายงานความพร้อมของข้อมูล — PM PLAN (แผนการทำ PM)
A2: แหล่งข้อมูล: ชีต 'query (10)' / ตาราง Table_query__10 (SharePoint List Export) — สแกนครบทุกแถว ไม่ได้สุ่มตัวอย่าง
A4: 1. ภาพรวม / Overview
A5: จำนวนแถวข้อมูล (rows) | B5: =ROWS(Table_query__10[]) -> 2820
A6: จำนวนคอลัมน์ (columns) | B6: =COLUMNS(Table_query__10[]) -> 37
A7: ID ไม่ซ้ำ (unique key) | B7: {=IF(SUMPRODUCT(1/COUNTIF(Table_query__10[ID],Table_query__10[ID]))=ROWS(Table_query__10[]),"✅ ไม่ซ้ำ 100% — ใช้เป็น primary key ได้","❌ พบค่าซ้ำ")} -> ✅ ไม่ซ้ำ 100% — ใช้เป็น primary key ได้
A8: จำนวนเครื่องจักร (QRCODE ไม่ซ้ำ) | B8: QRCODE เป็นรหัสเครื่อง จึงซ้ำได้ตามปกติ (เช่น GR-241 = 26 แถว) — ห้ามใช้เป็นคีย์
A9: มูลค่าอะไหล่รวม (Cost) | B9: =SUM(Table_query__10[Cost]) -> 881217.16
A10: แถวที่มี Cost > 0 | B10: =COUNTIF(Table_query__10[Cost],">0") -> 115
A11: งานที่ปิดแล้ว (StatusItems = เสร็จสิ้น) | B11: =COUNTIF(Table_query__10[StatusItems],"เสร็จสิ้น") -> 1851
A12: ช่วงวันที่ LastPMDate | B12: =TEXT(MIN(Table_query__10[LastPMDate]),"dd/mm/yyyy")&" ถึง "&TEXT(MAX(Table_query__10[LastPMDate]),"dd/mm/yyyy") -> 27/01/2024 ถึง 29/04/2029
A13: ช่วงวันที่ NextPMDate | B13: =TEXT(MIN(Table_query__10[NextPMDate]),"dd/mm/yyyy")&" ถึง "&TEXT(MAX(Table_query__10[NextPMDate]),"dd/mm/yyyy") -> 02/11/2024 ถึง 21/05/2086
A15: 2. โปรไฟล์รายคอลัมน์ / Per-column profile
A16: คอลัมน์ | B16: มีค่า | C16: ว่าง | D16: % ที่กรอก | E16: ค่าที่ต่างกัน | F16: สถานะ | G16: เหตุผล / สิ่งที่พบ
A17: ID | B17: =COUNTA(INDEX(Table_query__10[],0,MATCH($A17,Table_query__10[#Headers],0))) -> 2820 | C17: =ROWS(Table_query__10[])-B17 -> 0 | D17: =B17/ROWS(Table_query__10[]) -> 1 | E17: 2820 | F17: ✅ | G17: ไม่ซ้ำทุกแถว ใช้เป็น primary key ได้
A18: Ref_ID_Work01 | B18: =COUNTA(INDEX(Table_query__10[],0,MATCH($A18,Table_query__10[#Headers],0))) -> 1985 | C18: =ROWS(Table_query__10[])-B18 -> 835 | D18: =B18/ROWS(Table_query__10[]) -> 0.70390071 | E18: 1985 | F18: ⚠️ | G18: ว่าง 835 แถว — เชื่อมกับใบแจ้งซ่อมได้เพียงบางส่วน
A19: Ref_Part_Change_ID | B19: =COUNTA(INDEX(Table_query__10[],0,MATCH($A19,Table_query__10[#Headers],0))) -> 0 | C19: =ROWS(Table_query__10[])-B19 -> 2820 | D19: =B19/ROWS(Table_query__10[]) -> 0 | E19: 0 | F19: ❌ | G19: ว่าง 100% — ไม่มีข้อมูล ควรตัดออก
A20: Ref_Tool_Life_ID | B20: =COUNTA(INDEX(Table_query__10[],0,MATCH($A20,Table_query__10[#Headers],0))) -> 0 | C20: =ROWS(Table_query__10[])-B20 -> 2820 | D20: =B20/ROWS(Table_query__10[]) -> 0 | E20: 0 | F20: ❌ | G20: ว่าง 100% — ไม่มีข้อมูล ควรตัดออก
A21: Ref_PM_History_ID | B21: =COUNTA(INDEX(Table_query__10[],0,MATCH($A21,Table_query__10[#Headers],0))) -> 0 | C21: =ROWS(Table_query__10[])-B21 -> 2820 | D21: =B21/ROWS(Table_query__10[]) -> 0 | E21: 0 | F21: ❌ | G21: ว่าง 100% — ไม่มีข้อมูล ควรตัดออก
A22: PM_Type | B22: =COUNTA(INDEX(Table_query__10[],0,MATCH($A22,Table_query__10[#Headers],0))) -> 2817 | C22: =ROWS(Table_query__10[])-B22 -> 3 | D22: =B22/ROWS(Table_query__10[]) -> 0.99893617 | E22: 4 | F22: ✅ | G22: 4 ประเภท: TBM 2,469 / CBM 301 / UBM 29 / PdM 18 (ว่าง 3)
A23: StatusItems | B23: =COUNTA(INDEX(Table_query__10[],0,MATCH($A23,Table_query__10[#Headers],0))) -> 2768 | C23: =ROWS(Table_query__10[])-B23 -> 52 | D23: =B23/ROWS(Table_query__10[]) -> 0.98156028 | E23: 6 | F23: ⚠️ | G23: ว่าง 52 แถว; ค่าไทย 6 แบบ ควร map เป็นรหัสอังกฤษด้วย
A24: SectionResponse | B24: =COUNTA(INDEX(Table_query__10[],0,MATCH($A24,Table_query__10[#Headers],0))) -> 2817 | C24: =ROWS(Table_query__10[])-B24 -> 3 | D24: =B24/ROWS(Table_query__10[]) -> 0.99893617 | E24: 1 | F24: ❌ | G24: ค่าเดียวทั้งตาราง (Preventive Maintenance) — ไม่มีประโยชน์ในการวิเคราะห์
A25: TypeWork | B25: =COUNTA(INDEX(Table_query__10[],0,MATCH($A25,Table_query__10[#Headers],0))) -> 2817 | C25: =ROWS(Table_query__10[])-B25 -> 3 | D25: =B25/ROWS(Table_query__10[]) -> 0.99893617 | E25: 2 | F25: ✅ | G25: Mechanical 1,754 / Electrical 1,063 (ว่าง 3)
A26: PositionName | B26: =COUNTA(INDEX(Table_query__10[],0,MATCH($A26,Table_query__10[#Headers],0))) -> 2817 | C26: =ROWS(Table_query__10[])-B26 -> 3 | D26: =B26/ROWS(Table_query__10[]) -> 0.99893617 | E26: 70 | F26: ⚠️ | G26: มีช่องว่างหน้า/หลังข้อความ 320 แถว ทำให้จัดกลุ่มผิด
A27: LineLocation | B27: =COUNTA(INDEX(Table_query__10[],0,MATCH($A27,Table_query__10[#Headers],0))) -> 2817 | C27: =ROWS(Table_query__10[])-B27 -> 3 | D27: =B27/ROWS(Table_query__10[]) -> 0.99893617 | E27: 37 | F27: ✅ | G27: 37 ไลน์ ค่าสะอาด ใช้จัดกลุ่มได้ทันที
A28: MachineName | B28: =COUNTA(INDEX(Table_query__10[],0,MATCH($A28,Table_query__10[#Headers],0))) -> 2817 | C28: =ROWS(Table_query__10[])-B28 -> 3 | D28: =B28/ROWS(Table_query__10[]) -> 0.99893617 | E28: >200 | F28: ⚠️ | G28: ชื่อยาว บางแถวมีรหัสเครื่องใน () เช่น (GR-716) ควรแยกออก
A29: QRCODE | B29: =COUNTA(INDEX(Table_query__10[],0,MATCH($A29,Table_query__10[#Headers],0))) -> 2801 | C29: =ROWS(Table_query__10[])-B29 -> 19 | D29: =B29/ROWS(Table_query__10[]) -> 0.99326241 | E29: >200 | F29: ⚠️ | G29: ว่าง 19 แถว; ซ้ำได้ตามปกติ (1 เครื่องมีหลายรายการ PM)
A30: Items | B30: =COUNTA(INDEX(Table_query__10[],0,MATCH($A30,Table_query__10[#Headers],0))) -> 2817 | C30: =ROWS(Table_query__10[])-B30 -> 3 | D30: =B30/ROWS(Table_query__10[]) -> 0.99893617 | E30: >200 | F30: ⚠️ | G30: มีช่องว่างหน้า/หลัง 1,119 แถว; ข้อความใน () เป็นสเปกจริง ไม่ควรลบ
A31: Action | B31: =COUNTA(INDEX(Table_query__10[],0,MATCH($A31,Table_query__10[#Headers],0))) -> 2817 | C31: =ROWS(Table_query__10[])-B31 -> 3 | D31: =B31/ROWS(Table_query__10[]) -> 0.99893617 | E31: 6 | F31: ✅ | G31: Inspection 1,209 / Part Change 1,131 / Cleaning 368 / อื่น ๆ
A32: Priority | B32: =COUNTA(INDEX(Table_query__10[],0,MATCH($A32,Table_query__10[#Headers],0))) -> 2820 | C32: =ROWS(Table_query__10[])-B32 -> 0 | D32: =B32/ROWS(Table_query__10[]) -> 1 | E32: 4 | F32: ✅ | G32: Medium 2,663 / Important 133 / Low 18 / Urgent 6
A33: Spare_ID | B33: =COUNTA(INDEX(Table_query__10[],0,MATCH($A33,Table_query__10[#Headers],0))) -> 32 | C33: =ROWS(Table_query__10[])-B33 -> 2788 | D33: =B33/ROWS(Table_query__10[]) -> 0.011347518 | E33: 15 | F33: ❌ | G33: ว่าง 2,788 แถว (98.9%) — วิเคราะห์อะไหล่จากคอลัมน์นี้ไม่ได้
A34: PartName | B34: =COUNTA(INDEX(Table_query__10[],0,MATCH($A34,Table_query__10[#Headers],0))) -> 1063 | C34: =ROWS(Table_query__10[])-B34 -> 1757 | D34: =B34/ROWS(Table_query__10[]) -> 0.37695035 | E34: 87 | F34: ⚠️ | G34: ว่าง 1,757 แถว (62%) + ช่องว่างหน้า/หลัง 31 แถว
A35: Model | B35: =COUNTA(INDEX(Table_query__10[],0,MATCH($A35,Table_query__10[#Headers],0))) -> 1008 | C35: =ROWS(Table_query__10[])-B35 -> 1812 | D35: =B35/ROWS(Table_query__10[]) -> 0.35744681 | E35: >200 | F35: ⚠️ | G35: ว่าง 1,812 แถว (64%); ข้อความใน () ปนกันทั้งสเปกและหมายเหตุ
A36: Qty | B36: =COUNTA(INDEX(Table_query__10[],0,MATCH($A36,Table_query__10[#Headers],0))) -> 505 | C36: =ROWS(Table_query__10[])-B36 -> 2315 | D36: =B36/ROWS(Table_query__10[]) -> 0.17907801 | E36: 4 | F36: ❌ | G36: เก็บเป็นข้อความ 505 แถว (บวก/รวมไม่ได้) และมีค่า 0 อยู่ 25 แถว
A37: Cost | B37: =COUNTA(INDEX(Table_query__10[],0,MATCH($A37,Table_query__10[#Headers],0))) -> 2820 | C37: =ROWS(Table_query__10[])-B37 -> 0 | D37: =B37/ROWS(Table_query__10[]) -> 1 | E37: 35 | F37: ⚠️ | G37: 2,705 แถว (96%) เป็น 0 — วิเคราะห์ต้นทุนได้เฉพาะ 115 แถว
A38: PeriodDay | B38: =COUNTA(INDEX(Table_query__10[],0,MATCH($A38,Table_query__10[#Headers],0))) -> 2813 | C38: =ROWS(Table_query__10[])-B38 -> 7 | D38: =B38/ROWS(Table_query__10[]) -> 0.99751773 | E38: 45 | F38: ⚠️ | G38: มีค่า 0 วัน 102 แถว และว่าง 7 แถว — รอบ PM ไม่สมเหตุสมผล
A39: PlanMonth | B39: =COUNTA(INDEX(Table_query__10[],0,MATCH($A39,Table_query__10[#Headers],0))) -> 2817 | C39: =ROWS(Table_query__10[])-B39 -> 3 | D39: =B39/ROWS(Table_query__10[]) -> 0.99893617 | E39: >200 | F39: ✅ | G39: เป็นวันที่จริง (m/d/yyyy) ครบ 2,817 แถว
A40: ActualMonth | B40: =COUNTA(INDEX(Table_query__10[],0,MATCH($A40,Table_query__10[#Headers],0))) -> 1571 | C40: =ROWS(Table_query__10[])-B40 -> 1249 | D40: =B40/ROWS(Table_query__10[]) -> 0.5570922 | E40: 47 | F40: ⚠️ | G40: ว่าง 1,249 แถว — งานที่ยังไม่ทำจริง (สอดคล้องกับสถานะบางส่วน)
A41: LastPMDate | B41: =COUNTA(INDEX(Table_query__10[],0,MATCH($A41,Table_query__10[#Headers],0))) -> 2790 | C41: =ROWS(Table_query__10[])-B41 -> 30 | D41: =B41/ROWS(Table_query__10[]) -> 0.9893617 | E41: >200 | F41: ⚠️ | G41: ว่าง 30 แถว; มีวันที่อนาคตถึง 29/04/2029 ซึ่งขัดกับความหมาย 'ครั้งล่าสุด'
A42: NextPMDate | B42: =COUNTA(INDEX(Table_query__10[],0,MATCH($A42,Table_query__10[#Headers],0))) -> 2803 | C42: =ROWS(Table_query__10[])-B42 -> 17 | D42: =B42/ROWS(Table_query__10[]) -> 0.99397163 | E42: >200 | F42: ⚠️ | G42: ว่าง 17 แถว; มีค่าผิดปกติถึงปี 2086 (คีย์ผิด)
...

Sheet Cleaning_Rules
A1: กฎการทำความสะอาดข้อมูล / Cleaning Rules
A2: ⚠️ แก้ค่าในชีตนี้ได้เลย ชีต Clean_PM_Plan จะอัปเดตตาม — หากต้องเพิ่มกฎ ให้แทรกแถว 'ภายใน' ช่วงที่ระบุ (ห้ามพิมพ์ต่อท้ายใต้ช่วง เพราะสูตรจะไม่เห็น)
A4: บล็อก 1: StatusItems → Status_EN (ช่วงที่สูตรใช้: A5:B10)
A5: เสร็จสิ้น | B5: COMPLETED
A6: แผนใหม่ | B6: NEW_PLAN
A7: กำลังดำเนินการ | B7: IN_PROGRESS
A8: แก้ไขแผน | B8: PLAN_REVISED
A9: เลื่อนแผน | B9: POSTPONED
A10: ยกเลิกแผน | B10: CANCELLED
A13: บล็อก 2: PM_Type → PM_Type_Code (ช่วงที่สูตรใช้: A14:B17)
A14: Time-based Maintenance | B14: TBM
A15: Condition-based Maintenance | B15: CBM
A16: Usage-based Maintenance | B16: UBM
A17: Predictive Maintenance | B17: PdM
A20: บล็อก 3: ค่าหลอก/ค่าไม่ถูกต้อง → แปลงเป็นค่าว่าง (ช่วงที่สูตรใช้: A21:A26)
A21: -
A22: N/A
A23: NA
A24: TBD
A25: NULL
A26: .
A28: บล็อก 4: คำอธิบายคอลัมน์ที่สร้างใหม่ (อ่านอย่างเดียว)
A29: คอลัมน์ | B29: ตรรกะ
A30: Machine_Base_Name | B30: ชื่อเครื่องส่วนหน้าก่อนวงเล็บ ตัดช่องว่างและทำเป็นตัวพิมพ์ใหญ่
